Workbook

Sheet Summary
A1: Vision models that could paint, priced on OpenRouter (2026-09-28)
A3: set | B3: models | C3: light $ | D3: typical $ | E3: heavy $ | F3: one pass $ | G3: three passes $
A4: Latest | B4: 47 | C4: ='Latest (47)'!K50 | D4: ='Latest (47)'!L50 | E4: ='Latest (47)'!M50 | F4: ='Latest (47)'!N50 | G4: ='Latest (47)'!O50
A5: Present & past | B5: 156 | C5: ='Present & past (156)'!K159 | D5: ='Present & past (156)'!L159 | E5: ='Present & past (156)'!M159 | F5: ='Present & past (156)'!N159 | G5: ='Present & past (156)'!O159
A6: Sum of both | B6: =B4+B5 | C6: =C4+C5 | D6: =D4+D5 | E6: =E4+E5 | F6: =F4+F5 | G6: =G4+G5
A8: One pass = one light, one typical and one heavy painting per model (4 sittings each; profiles on the Profiles sheet).
A9: Latest: the newest model per line released since 2026-03-28. Present & past: every version still on OpenRouter.
A10: Both: images in, tool calls, interactive; no routers or orchestrators (Unbiased's Pareto, an ensemble, kept on purpose);
A11: no OpenAI Pro models; no image-generation models. The sum counts the latest models twice (they're in both sets).
A12: Cost = prompt x (8% input + 89% cache read + 3% cache write) + output + images, at list prices; no cache price = input price.
A13: Ballpark: x0.5 to x2 (tokenizers, image tokens and thinking length differ). If caching fails, x3 to x5.
A14: Source: https://openrouter.ai/api/v1/models (fetched 2026-09-28); token profiles from our session logs.
A15: Yellow rows: models we have painted with.

Sheet Latest (47)
A1: # | B1: model | C1: released | D1: note | E1: painted with it | F1: $/M input | G1: $/M output | H1: $/M cache read | I1: $/M cache write | J1: $/image | K1: light $ | L1: typical $ | M1: heavy $ | N1: one pass $ | O1: three passes $
A2: 1 | B2: openai/gpt-6-astra | C2: 2026-09-04 | E2: yes | F2: 10 | G2: 50 | H2: 1 | I2: 12.5 | K2: =(Profiles!$B$3*(Profiles!$B$9*F2+Profiles!$B$8*IF(H2="",F2,H2)+Profiles!$B$10*IF(I2="",F2,I2))+Profiles!$C$3*G2)/1000000+Profiles!$D$3*IF(J2="",0,J2) | L2: =(Profiles!$B$4*(Profiles!$B$9*F2+Profiles!$B$8*IF(H2="",F2,H2)+Profiles!$B$10*IF(I2="",F2,I2))+Profiles!$C$4*G2)/1000000+Profiles!$D$4*IF(J2="",0,J2) | M2: =(Profiles!$B$5*(Profiles!$B$9*F2+Profiles!$B$8*IF(H2="",F2,H2)+Profiles!$B$10*IF(I2="",F2,I2))+Profiles!$C$5*G2)/1000000+Profiles!$D$5*IF(J2="",0,J2) | N2: =K2+L2+M2 | O2: =3*N2
A3: 2 | B3: anthropic/claude-fable-5.1 | C3: 2026-09-01 | E3: yes | F3: 10 | G3: 50 | H3: 0.25 | I3: 12.5 | K3: =(Profiles!$B$3*(Profiles!$B$9*F3+Profiles!$B$8*IF(H3="",F3,H3)+Profiles!$B$10*IF(I3="",F3,I3))+Profiles!$C$3*G3)/1000000+Profiles!$D$3*IF(J3="",0,J3) | L3: =(Profiles!$B$4*(Profiles!$B$9*F3+Profiles!$B$8*IF(H3="",F3,H3)+Profiles!$B$10*IF(I3="",F3,I3))+Profiles!$C$4*G3)/1000000+Profiles!$D$4*IF(J3="",0,J3) | M3: =(Profiles!$B$5*(Profiles!$B$9*F3+Profiles!$B$8*IF(H3="",F3,H3)+Profiles!$B$10*IF(I3="",F3,I3))+Profiles!$C$5*G3)/1000000+Profiles!$D$5*IF(J3="",0,J3) | N3: =K3+L3+M3 | O3: =3*N3
A4: 3 | B4: qwen/qwen3.8-max-prime | C4: 2026-09-23 | F4: 4 | G4: 12 | H4: 0.5 | K4: =(Profiles!$B$3*(Profiles!$B$9*F4+Profiles!$B$8*IF(H4="",F4,H4)+Profiles!$B$10*IF(I4="",F4,I4))+Profiles!$C$3*G4)/1000000+Profiles!$D$3*IF(J4="",0,J4) | L4: =(Profiles!$B$4*(Profiles!$B$9*F4+Profiles!$B$8*IF(H4="",F4,H4)+Profiles!$B$10*IF(I4="",F4,I4))+Profiles!$C$4*G4)/1000000+Profiles!$D$4*IF(J4="",0,J4) | M4: =(Profiles!$B$5*(Profiles!$B$9*F4+Profiles!$B$8*IF(H4="",F4,H4)+Profiles!$B$10*IF(I4="",F4,I4))+Profiles!$C$5*G4)/1000000+Profiles!$D$5*IF(J4="",0,J4) | N4: =K4+L4+M4 | O4: =3*N4
A5: 4 | B5: anthropic/claude-opus-5.5 | C5: 2026-09-22 | E5: yes | F5: 4 | G5: 20 | H5: 0.2 | I5: 5 | K5: =(Profiles!$B$3*(Profiles!$B$9*F5+Profiles!$B$8*IF(H5="",F5,H5)+Profiles!$B$10*IF(I5="",F5,I5))+Profiles!$C$3*G5)/1000000+Profiles!$D$3*IF(J5="",0,J5) | L5: =(Profiles!$B$4*(Profiles!$B$9*F5+Profiles!$B$8*IF(H5="",F5,H5)+Profiles!$B$10*IF(I5="",F5,I5))+Profiles!$C$4*G5)/1000000+Profiles!$D$4*IF(J5="",0,J5) | M5: =(Profiles!$B$5*(Profiles!$B$9*F5+Profiles!$B$8*IF(H5="",F5,H5)+Profiles!$B$10*IF(I5="",F5,I5))+Profiles!$C$5*G5)/1000000+Profiles!$D$5*IF(J5="",0,J5) | N5: =K5+L5+M5 | O5: =3*N5
A6: 5 | B6: fireworks/ember-1 | C6: 2026-09-24 | D6: Kimi K3 fine-tune with shorter reasoning (likely cheaper than shown) | F6: 3 | G6: 15 | H6: 0.3 | K6: =(Profiles!$B$3*(Profiles!$B$9*F6+Profiles!$B$8*IF(H6="",F6,H6)+Profiles!$B$10*IF(I6="",F6,I6))+Profiles!$C$3*G6)/1000000+Profiles!$D$3*IF(J6="",0,J6) | L6: =(Profiles!$B$4*(Profiles!$B$9*F6+Profiles!$B$8*IF(H6="",F6,H6)+Profiles!$B$10*IF(I6="",F6,I6))+Profiles!$C$4*G6)/1000000+Profiles!$D$4*IF(J6="",0,J6) | M6: =(Profiles!$B$5*(Profiles!$B$9*F6+Profiles!$B$8*IF(H6="",F6,H6)+Profiles!$B$10*IF(I6="",F6,I6))+Profiles!$C$5*G6)/1000000+Profiles!$D$5*IF(J6="",0,J6) | N6: =K6+L6+M6 | O6: =3*N6
A7: 6 | B7: moonshotai/kimi-k3 | C7: 2026-07-16 | E7: yes | F7: 3 | G7: 15 | H7: 0.3 | K7: =(Profiles!$B$3*(Profiles!$B$9*F7+Profiles!$B$8*IF(H7="",F7,H7)+Profiles!$B$10*IF(I7="",F7,I7))+Profiles!$C$3*G7)/1000000+Profiles!$D$3*IF(J7="",0,J7) | L7: =(Profiles!$B$4*(Profiles!$B$9*F7+Profiles!$B$8*IF(H7="",F7,H7)+Profiles!$B$10*IF(I7="",F7,I7))+Profiles!$C$4*G7)/1000000+Profiles!$D$4*IF(J7="",0,J7) | M7: =(Profiles!$B$5*(Profiles!$B$9*F7+Profiles!$B$8*IF(H7="",F7,H7)+Profiles!$B$10*IF(I7="",F7,I7))+Profiles!$C$5*G7)/1000000+Profiles!$D$5*IF(J7="",0,J7) | N7: =K7+L7+M7 | O7: =3*N7
A8: 7 | B8: xiaomi/mimo-v2.6-pro-ultraspeed | C8: 2026-09-21 | F8: 4.35 | G8: 8.7 | H8: 0.036 | K8: =(Profiles!$B$3*(Profiles!$B$9*F8+Profiles!$B$8*IF(H8="",F8,H8)+Profiles!$B$10*IF(I8="",F8,I8))+Profiles!$C$3*G8)/1000000+Profiles!$D$3*IF(J8="",0,J8) | L8: =(Profiles!$B$4*(Profiles!$B$9*F8+Profiles!$B$8*IF(H8="",F8,H8)+Profiles!$B$10*IF(I8="",F8,I8))+Profiles!$C$4*G8)/1000000+Profiles!$D$4*IF(J8="",0,J8) | M8: =(Profiles!$B$5*(Profiles!$B$9*F8+Profiles!$B$8*IF(H8="",F8,H8)+Profiles!$B$10*IF(I8="",F8,I8))+Profiles!$C$5*G8)/1000000+Profiles!$D$5*IF(J8="",0,J8) | N8: =K8+L8+M8 | O8: =3*N8
A9: 8 | B9: x-ai/grok-4.7 | C9: 2026-09-21 | F9: 1.6 | G9: 4.8 | H9: 0.4 | K9: =(Profiles!$B$3*(Profiles!$B$9*F9+Profiles!$B$8*IF(H9="",F9,H9)+Profiles!$B$10*IF(I9="",F9,I9))+Profiles!$C$3*G9)/1000000+Profiles!$D$3*IF(J9="",0,J9) | L9: =(Profiles!$B$4*(Profiles!$B$9*F9+Profiles!$B$8*IF(H9="",F9,H9)+Profiles!$B$10*IF(I9="",F9,I9))+Profiles!$C$4*G9)/1000000+Profiles!$D$4*IF(J9="",0,J9) | M9: =(Profiles!$B$5*(Profiles!$B$9*F9+Profiles!$B$8*IF(H9="",F9,H9)+Profiles!$B$10*IF(I9="",F9,I9))+Profiles!$C$5*G9)/1000000+Profiles!$D$5*IF(J9="",0,J9) | N9: =K9+L9+M9 | O9: =3*N9
A10: 9 | B10: unbiased/pareto | C10: 2026-09-18 | D10: ensemble (several unnamed models per request): kept on purpose | F10: 2.5 | G10: 7.5 | H10: 0.25 | K10: =(Profiles!$B$3*(Profiles!$B$9*F10+Profiles!$B$8*IF(H10="",F10,H10)+Profiles!$B$10*IF(I10="",F10,I10))+Profiles!$C$3*G10)/1000000+Profiles!$D$3*IF(J10="",0,J10) | L10: =(Profiles!$B$4*(Profiles!$B$9*F10+Profiles!$B$8*IF(H10="",F10,H10)+Profiles!$B$10*IF(I10="",F10,I10))+Profiles!$C$4*G10)/1000000+Profiles!$D$4*IF(J10="",0,J10) | M10: =(Profiles!$B$5*(Profiles!$B$9*F10+Profiles!$B$8*IF(H10="",F10,H10)+Profiles!$B$10*IF(I10="",F10,I10))+Profiles!$C$5*G10)/1000000+Profiles!$D$5*IF(J10="",0,J10) | N10: =K10+L10+M10 | O10: =3*N10
A11: 10 | B11: bytedance-seed/seed-2.0-code | C11: 2026-08-12 | F11: 0.5 | G11: 3 | K11: =(Profiles!$B$3*(Profiles!$B$9*F11+Profiles!$B$8*IF(H11="",F11,H11)+Profiles!$B$10*IF(I11="",F11,I11))+Profiles!$C$3*G11)/1000000+Profiles!$D$3*IF(J11="",0,J11) | L11: =(Profiles!$B$4*(Profiles!$B$9*F11+Profiles!$B$8*IF(H11="",F11,H11)+Profiles!$B$10*IF(I11="",F11,I11))+Profiles!$C$4*G11)/1000000+Profiles!$D$4*IF(J11="",0,J11) | M11: =(Profiles!$B$5*(Profiles!$B$9*F11+Profiles!$B$8*IF(H11="",F11,H11)+Profiles!$B$10*IF(I11="",F11,I11))+Profiles!$C$5*G11)/1000000+Profiles!$D$5*IF(J11="",0,J11) | N11: =K11+L11+M11 | O11: =3*N11
A12: 11 | B12: bytedance-seed/seed-2-1-turbo | C12: 2026-08-12 | F12: 0.5 | G12: 2.5 | K12: =(Profiles!$B$3*(Profiles!$B$9*F12+Profiles!$B$8*IF(H12="",F12,H12)+Profiles!$B$10*IF(I12="",F12,I12))+Profiles!$C$3*G12)/1000000+Profiles!$D$3*IF(J12="",0,J12) | L12: =(Profiles!$B$4*(Profiles!$B$9*F12+Profiles!$B$8*IF(H12="",F12,H12)+Profiles!$B$10*IF(I12="",F12,I12))+Profiles!$C$4*G12)/1000000+Profiles!$D$4*IF(J12="",0,J12) | M12: =(Profiles!$B$5*(Profiles!$B$9*F12+Profiles!$B$8*IF(H12="",F12,H12)+Profiles!$B$10*IF(I12="",F12,I12))+Profiles!$C$5*G12)/1000000+Profiles!$D$5*IF(J12="",0,J12) | N12: =K12+L12+M12 | O12: =3*N12
A13: 12 | B13: openai/gpt-5.6-terra | C13: 2026-07-09 | F13: 2 | G13: 12 | H13: 0.2 | I13: 2.5 | K13: =(Profiles!$B$3*(Profiles!$B$9*F13+Profiles!$B$8*IF(H13="",F13,H13)+Profiles!$B$10*IF(I13="",F13,I13))+Profiles!$C$3*G13)/1000000+Profiles!$D$3*IF(J13="",0,J13) | L13: =(Profiles!$B$4*(Profiles!$B$9*F13+Profiles!$B$8*IF(H13="",F13,H13)+Profiles!$B$10*IF(I13="",F13,I13))+Profiles!$C$4*G13)/1000000+Profiles!$D$4*IF(J13="",0,J13) | M13: =(Profiles!$B$5*(Profiles!$B$9*F13+Profiles!$B$8*IF(H13="",F13,H13)+Profiles!$B$10*IF(I13="",F13,I13))+Profiles!$C$5*G13)/1000000+Profiles!$D$5*IF(J13="",0,J13) | N13: =K13+L13+M13 | O13: =3*N13
A14: 13 | B14: qwen/qwen3.8-max-0902 | C14: 2026-09-03 | F14: 2 | G14: 6 | H14: 0.25 | I14: 2.5 | K14: =(Profiles!$B$3*(Profiles!$B$9*F14+Profiles!$B$8*IF(H14="",F14,H14)+Profiles!$B$10*IF(I14="",F14,I14))+Profiles!$C$3*G14)/1000000+Profiles!$D$3*IF(J14="",0,J14) | L14: =(Profiles!$B$4*(Profiles!$B$9*F14+Profiles!$B$8*IF(H14="",F14,H14)+Profiles!$B$10*IF(I14="",F14,I14))+Profiles!$C$4*G14)/1000000+Profiles!$D$4*IF(J14="",0,J14) | M14: =(Profiles!$B$5*(Profiles!$B$9*F14+Profiles!$B$8*IF(H14="",F14,H14)+Profiles!$B$10*IF(I14="",F14,I14))+Profiles!$C$5*G14)/1000000+Profiles!$D$5*IF(J14="",0,J14) | N14: =K14+L14+M14 | O14: =3*N14
A15: 14 | B15: openai/gpt-6-sol | C15: 2026-09-22 | F15: 2 | G15: 10 | H15: 0.2 | I15: 2.5 | K15: =(Profiles!$B$3*(Profiles!$B$9*F15+Profiles!$B$8*IF(H15="",F15,H15)+Profiles!$B$10*IF(I15="",F15,I15))+Profiles!$C$3*G15)/1000000+Profiles!$D$3*IF(J15="",0,J15) | L15: =(Profiles!$B$4*(Profiles!$B$9*F15+Profiles!$B$8*IF(H15="",F15,H15)+Profiles!$B$10*IF(I15="",F15,I15))+Profiles!$C$4*G15)/1000000+Profiles!$D$4*IF(J15="",0,J15) | M15: =(Profiles!$B$5*(Profiles!$B$9*F15+Profiles!$B$8*IF(H15="",F15,H15)+Profiles!$B$10*IF(I15="",F15,I15))+Profiles!$C$5*G15)/1000000+Profiles!$D$5*IF(J15="",0,J15) | N15: =K15+L15+M15 | O15: =3*N15
A16: 15 | B16: anthropic/claude-sonnet-5 | C16: 2026-06-30 | F16: 2 | G16: 10 | H16: 0.2 | I16: 2.5 | K16: =(Profiles!$B$3*(Profiles!$B$9*F16+Profiles!$B$8*IF(H16="",F16,H16)+Profiles!$B$10*IF(I16="",F16,I16))+Profiles!$C$3*G16)/1000000+Profiles!$D$3*IF(J16="",0,J16) | L16: =(Profiles!$B$4*(Profiles!$B$9*F16+Profiles!$B$8*IF(H16="",F16,H16)+Profiles!$B$10*IF(I16="",F16,I16))+Profiles!$C$4*G16)/1000000+Profiles!$D$4*IF(J16="",0,J16) | M16: =(Profiles!$B$5*(Profiles!$B$9*F16+Profiles!$B$8*IF(H16="",F16,H16)+Profiles!$B$10*IF(I16="",F16,I16))+Profiles!$C$5*G16)/1000000+Profiles!$D$5*IF(J16="",0,J16) | N16: =K16+L16+M16 | O16: =3*N16
A17: 16 | B17: z-ai/glm-5v-turbo | C17: 2026-04-01 | F17: 1.2 | G17: 4 | H17: 0.24 | K17: =(Profiles!$B$3*(Profiles!$B$9*F17+Profiles!$B$8*IF(H17="",F17,H17)+Profiles!$B$10*IF(I17="",F17,I17))+Profiles!$C$3*G17)/1000000+Profiles!$D$3*IF(J17="",0,J17) | L17: =(Profiles!$B$4*(Profiles!$B$9*F17+Profiles!$B$8*IF(H17="",F17,H17)+Profiles!$B$10*IF(I17="",F17,I17))+Profiles!$C$4*G17)/1000000+Profiles!$D$4*IF(J17="",0,J17) | M17: =(Profiles!$B$5*(Profiles!$B$9*F17+Profiles!$B$8*IF(H17="",F17,H17)+Profiles!$B$10*IF(I17="",F17,I17))+Profiles!$C$5*G17)/1000000+Profiles!$D$5*IF(J17="",0,J17) | N17: =K17+L17+M17 | O17: =3*N17
A18: 17 | B18: mistralai/mistral-medium-3-5 | C18: 2026-04-30 | D18: cached tokens at 10% per Mistral (not listed on OpenRouter) | F18: 1.5 | G18: 7.5 | H18: 0.15 | K18: =(Profiles!$B$3*(Profiles!$B$9*F18+Profiles!$B$8*IF(H18="",F18,H18)+Profiles!$B$10*IF(I18="",F18,I18))+Profiles!$C$3*G18)/1000000+Profiles!$D$3*IF(J18="",0,J18) | L18: =(Profiles!$B$4*(Profiles!$B$9*F18+Profiles!$B$8*IF(H18="",F18,H18)+Profiles!$B$10*IF(I18="",F18,I18))+Profiles!$C$4*G18)/1000000+Profiles!$D$4*IF(J18="",0,J18) | M18: =(Profiles!$B$5*(Profiles!$B$9*F18+Profiles!$B$8*IF(H18="",F18,H18)+Profiles!$B$10*IF(I18="",F18,I18))+Profiles!$C$5*G18)/1000000+Profiles!$D$5*IF(J18="",0,J18) | N18: =K18+L18+M18 | O18: =3*N18
A19: 18 | B19: x-ai/grok-build-0.1 | C19: 2026-05-20 | D19: xAI's coding model | F19: 1 | G19: 2 | H19: 0.2 | K19: =(Profiles!$B$3*(Profiles!$B$9*F19+Profiles!$B$8*IF(H19="",F19,H19)+Profiles!$B$10*IF(I19="",F19,I19))+Profiles!$C$3*G19)/1000000+Profiles!$D$3*IF(J19="",0,J19) | L19: =(Profiles!$B$4*(Profiles!$B$9*F19+Profiles!$B$8*IF(H19="",F19,H19)+Profiles!$B$10*IF(I19="",F19,I19))+Profiles!$C$4*G19)/1000000+Profiles!$D$4*IF(J19="",0,J19) | M19: =(Profiles!$B$5*(Profiles!$B$9*F19+Profiles!$B$8*IF(H19="",F19,H19)+Profiles!$B$10*IF(I19="",F19,I19))+Profiles!$C$5*G19)/1000000+Profiles!$D$5*IF(J19="",0,J19) | N19: =K19+L19+M19 | O19: =3*N19
A20: 19 | B20: meta/muse-spark-1.3 | C20: 2026-09-02 | E20: yes | F20: 1.25 | G20: 4.25 | H20: 0.15 | K20: =(Profiles!$B$3*(Profiles!$B$9*F20+Profiles!$B$8*IF(H20="",F20,H20)+Profiles!$B$10*IF(I20="",F20,I20))+Profiles!$C$3*G20)/1000000+Profiles!$D$3*IF(J20="",0,J20) | L20: =(Profiles!$B$4*(Profiles!$B$9*F20+Profiles!$B$8*IF(H20="",F20,H20)+Profiles!$B$10*IF(I20="",F20,I20))+Profiles!$C$4*G20)/1000000+Profiles!$D$4*IF(J20="",0,J20) | M20: =(Profiles!$B$5*(Profiles!$B$9*F20+Profiles!$B$8*IF(H20="",F20,H20)+Profiles!$B$10*IF(I20="",F20,I20))+Profiles!$C$5*G20)/1000000+Profiles!$D$5*IF(J20="",0,J20) | N20: =K20+L20+M20 | O20: =3*N20
A21: 20 | B21: thinkingmachines/inkling | C21: 2026-07-17 | F21: 1 | G21: 4.05 | H21: 0.17 | K21: =(Profiles!$B$3*(Profiles!$B$9*F21+Profiles!$B$8*IF(H21="",F21,H21)+Profiles!$B$10*IF(I21="",F21,I21))+Profiles!$C$3*G21)/1000000+Profiles!$D$3*IF(J21="",0,J21) | L21: =(Profiles!$B$4*(Profiles!$B$9*F21+Profiles!$B$8*IF(H21="",F21,H21)+Profiles!$B$10*IF(I21="",F21,I21))+Profiles!$C$4*G21)/1000000+Profiles!$D$4*IF(J21="",0,J21) | M21: =(Profiles!$B$5*(Profiles!$B$9*F21+Profiles!$B$8*IF(H21="",F21,H21)+Profiles!$B$10*IF(I21="",F21,I21))+Profiles!$C$5*G21)/1000000+Profiles!$D$5*IF(J21="",0,J21) | N21: =K21+L21+M21 | O21: =3*N21
A22: 21 | B22: moonshotai/kimi-k2.7-code | C22: 2026-06-12 | F22: 0.6562 | G22: 3.3 | H22: 0.18 | K22: =(Profiles!$B$3*(Profiles!$B$9*F22+Profiles!$B$8*IF(H22="",F22,H22)+Profiles!$B$10*IF(I22="",F22,I22))+Profiles!$C$3*G22)/1000000+Profiles!$D$3*IF(J22="",0,J22) | L22: =(Profiles!$B$4*(Profiles!$B$9*F22+Profiles!$B$8*IF(H22="",F22,H22)+Profiles!$B$10*IF(I22="",F22,I22))+Profiles!$C$4*G22)/1000000+Profiles!$D$4*IF(J22="",0,J22) | M22: =(Profiles!$B$5*(Profiles!$B$9*F22+Profiles!$B$8*IF(H22="",F22,H22)+Profiles!$B$10*IF(I22="",F22,I22))+Profiles!$C$5*G22)/1000000+Profiles!$D$5*IF(J22="",0,J22) | N22: =K22+L22+M22 | O22: =3*N22
A23: 22 | B23: cohere/command-a-plus | C23: 2026-09-22 | F23: 0.3 | G23: 1.5 | H23: 0.15 | K23: =(Profiles!$B$3*(Profiles!$B$9*F23+Profiles!$B$8*IF(H23="",F23,H23)+Profiles!$B$10*IF(I23="",F23,I23))+Profiles!$C$3*G23)/1000000+Profiles!$D$3*IF(J23="",0,J23) | L23: =(Profiles!$B$4*(Profiles!$B$9*F23+Profiles!$B$8*IF(H23="",F23,H23)+Profiles!$B$10*IF(I23="",F23,I23))+Profiles!$C$4*G23)/1000000+Profiles!$D$4*IF(J23="",0,J23) | M23: =(Profiles!$B$5*(Profiles!$B$9*F23+Profiles!$B$8*IF(H23="",F23,H23)+Profiles!$B$10*IF(I23="",F23,I23))+Profiles!$C$5*G23)/1000000+Profiles!$D$5*IF(J23="",0,J23) | N23: =K23+L23+M23 | O23: =3*N23
A24: 23 | B24: perceptron/perceptron-mk1.5 | C24: 2026-09-25 | F24: 0.15 | G24: 1.5 | K24: =(Profiles!$B$3*(Profiles!$B$9*F24+Profiles!$B$8*IF(H24="",F24,H24)+Profiles!$B$10*IF(I24="",F24,I24))+Profiles!$C$3*G24)/1000000+Profiles!$D$3*IF(J24="",0,J24) | L24: =(Profiles!$B$4*(Profiles!$B$9*F24+Profiles!$B$8*IF(H24="",F24,H24)+Profiles!$B$10*IF(I24="",F24,I24))+Profiles!$C$4*G24)/1000000+Profiles!$D$4*IF(J24="",0,J24) | M24: =(Profiles!$B$5*(Profiles!$B$9*F24+Profiles!$B$8*IF(H24="",F24,H24)+Profiles!$B$10*IF(I24="",F24,I24))+Profiles!$C$5*G24)/1000000+Profiles!$D$5*IF(J24="",0,J24) | N24: =K24+L24+M24 | O24: =3*N24
A25: 24 | B25: google/gemini-3.8-flash | C25: 2026-09-02 | E25: yes | F25: 0.75 | G25: 3.75 | H25: 0.075 | I25: 0.041666667 | J25: 7.5e-07 | K25: =(Profiles!$B$3*(Profiles!$B$9*F25+Profiles!$B$8*IF(H25="",F25,H25)+Profiles!$B$10*IF(I25="",F25,I25))+Profiles!$C$3*G25)/1000000+Profiles!$D$3*IF(J25="",0,J25) | L25: =(Profiles!$B$4*(Profiles!$B$9*F25+Profiles!$B$8*IF(H25="",F25,H25)+Profiles!$B$10*IF(I25="",F25,I25))+Profiles!$C$4*G25)/1000000+Profiles!$D$4*IF(J25="",0,J25) | M25: =(Profiles!$B$5*(Profiles!$B$9*F25+Profiles!$B$8*IF(H25="",F25,H25)+Profiles!$B$10*IF(I25="",F25,I25))+Profiles!$C$5*G25)/1000000+Profiles!$D$5*IF(J25="",0,J25) | N25: =K25+L25+M25 | O25: =3*N25
A26: 25 | B26: thinkingmachines/inkling-small | C26: 2026-07-30 | F26: 0.45 | G26: 1.2 | H26: 0.1 | K26: =(Profiles!$B$3*(Profiles!$B$9*F26+Profiles!$B$8*IF(H26="",F26,H26)+Profiles!$B$10*IF(I26="",F26,I26))+Profiles!$C$3*G26)/1000000+Profiles!$D$3*IF(J26="",0,J26) | L26: =(Profiles!$B$4*(Profiles!$B$9*F26+Profiles!$B$8*IF(H26="",F26,H26)+Profiles!$B$10*IF(I26="",F26,I26))+Profiles!$C$4*G26)/1000000+Profiles!$D$4*IF(J26="",0,J26) | M26: =(Profiles!$B$5*(Profiles!$B$9*F26+Profiles!$B$8*IF(H26="",F26,H26)+Profiles!$B$10*IF(I26="",F26,I26))+Profiles!$C$5*G26)/1000000+Profiles!$D$5*IF(J26="",0,J26) | N26: =K26+L26+M26 | O26: =3*N26
A27: 26 | B27: qwen/qwen3.8-27b | C27: 2026-08-14 | F27: 0.42 | G27: 3 | H27: 0.085 | K27: =(Profiles!$B$3*(Profiles!$B$9*F27+Profiles!$B$8*IF(H27="",F27,H27)+Profiles!$B$10*IF(I27="",F27,I27))+Profiles!$C$3*G27)/1000000+Profiles!$D$3*IF(J27="",0,J27) | L27: =(Profiles!$B$4*(Profiles!$B$9*F27+Profiles!$B$8*IF(H27="",F27,H27)+Profiles!$B$10*IF(I27="",F27,I27))+Profiles!$C$4*G27)/1000000+Profiles!$D$4*IF(J27="",0,J27) | M27: =(Profiles!$B$5*(Profiles!$B$9*F27+Profiles!$B$8*IF(H27="",F27,H27)+Profiles!$B$10*IF(I27="",F27,I27))+Profiles!$C$5*G27)/1000000+Profiles!$D$5*IF(J27="",0,J27) | N27: =K27+L27+M27 | O27: =3*N27
A28: 27 | B28: z-ai/glm-5.3-flashx | C28: 2026-09-18 | F28: 0.37 | G28: 1.25 | H28: 0.09 | K28: =(Profiles!$B$3*(Profiles!$B$9*F28+Profiles!$B$8*IF(H28="",F28,H28)+Profiles!$B$10*IF(I28="",F28,I28))+Profiles!$C$3*G28)/1000000+Profiles!$D$3*IF(J28="",0,J28) | L28: =(Profiles!$B$4*(Profiles!$B$9*F28+Profiles!$B$8*IF(H28="",F28,H28)+Profiles!$B$10*IF(I28="",F28,I28))+Profiles!$C$4*G28)/1000000+Profiles!$D$4*IF(J28="",0,J28) | M28: =(Profiles!$B$5*(Profiles!$B$9*F28+Profiles!$B$8*IF(H28="",F28,H28)+Profiles!$B$10*IF(I28="",F28,I28))+Profiles!$C$5*G28)/1000000+Profiles!$D$5*IF(J28="",0,J28) | N28: =K28+L28+M28 | O28: =3*N28
A29: 28 | B29: qwen/qwen3.7-plus | C29: 2026-06-03 | F29: 0.32 | G29: 1.28 | H29: 0.064 | I29: 0.4 | K29: =(Profiles!$B$3*(Profiles!$B$9*F29+Profiles!$B$8*IF(H29="",F29,H29)+Profiles!$B$10*IF(I29="",F29,I29))+Profiles!$C$3*G29)/1000000+Profiles!$D$3*IF(J29="",0,J29) | L29: =(Profiles!$B$4*(Profiles!$B$9*F29+Profiles!$B$8*IF(H29="",F29,H29)+Profiles!$B$10*IF(I29="",F29,I29))+Profiles!$C$4*G29)/1000000+Profiles!$D$4*IF(J29="",0,J29) | M29: =(Profiles!$B$5*(Profiles!$B$9*F29+Profiles!$B$8*IF(H29="",F29,H29)+Profiles!$B$10*IF(I29="",F29,I29))+Profiles!$C$5*G29)/1000000+Profiles!$D$5*IF(J29="",0,J29) | N29: =K29+L29+M29 | O29: =3*N29
A30: 29 | B30: minimax/minimax-m3 | C30: 2026-05-31 | F30: 0.3 | G30: 1.2 | H30: 0.06 | K30: =(Profiles!$B$3*(Profiles!$B$9*F30+Profiles!$B$8*IF(H30="",F30,H30)+Profiles!$B$10*IF(I30="",F30,I30))+Profiles!$C$3*G30)/1000000+Profiles!$D$3*IF(J30="",0,J30) | L30: =(Profiles!$B$4*(Profiles!$B$9*F30+Profiles!$B$8*IF(H30="",F30,H30)+Profiles!$B$10*IF(I30="",F30,I30))+Profiles!$C$4*G30)/1000000+Profiles!$D$4*IF(J30="",0,J30) | M30: =(Profiles!$B$5*(Profiles!$B$9*F30+Profiles!$B$8*IF(H30="",F30,H30)+Profiles!$B$10*IF(I30="",F30,I30))+Profiles!$C$5*G30)/1000000+Profiles!$D$5*IF(J30="",0,J30) | N30: =K30+L30+M30 | O30: =3*N30
A31: 30 | B31: prism-ml/ternary-bonsai-2-27b | C31: 2026-09-18 | F31: 0.075 | G31: 0.5 | K31: =(Profiles!$B$3*(Profiles!$B$9*F31+Profiles!$B$8*IF(H31="",F31,H31)+Profiles!$B$10*IF(I31="",F31,I31))+Profiles!$C$3*G31)/1000000+Profiles!$D$3*IF(J31="",0,J31) | L31: =(Profiles!$B$4*(Profiles!$B$9*F31+Profiles!$B$8*IF(H31="",F31,H31)+Profiles!$B$10*IF(I31="",F31,I31))+Profiles!$C$4*G31)/1000000+Profiles!$D$4*IF(J31="",0,J31) | M31: =(Profiles!$B$5*(Profiles!$B$9*F31+Profiles!$B$8*IF(H31="",F31,H31)+Profiles!$B$10*IF(I31="",F31,I31))+Profiles!$C$5*G31)/1000000+Profiles!$D$5*IF(J31="",0,J31) | N31: =K31+L31+M31 | O31: =3*N31
A32: 31 | B32: meta/muse-glimmer-30b | C32: 2026-08-09 | F32: 0.3 | G32: 1.2 | H32: 0.04 | K32: =(Profiles!$B$3*(Profiles!$B$9*F32+Profiles!$B$8*IF(H32="",F32,H32)+Profiles!$B$10*IF(I32="",F32,I32))+Profiles!$C$3*G32)/1000000+Profiles!$D$3*IF(J32="",0,J32) | L32: =(Profiles!$B$4*(Profiles!$B$9*F32+Profiles!$B$8*IF(H32="",F32,H32)+Profiles!$B$10*IF(I32="",F32,I32))+Profiles!$C$4*G32)/1000000+Profiles!$D$4*IF(J32="",0,J32) | M32: =(Profiles!$B$5*(Profiles!$B$9*F32+Profiles!$B$8*IF(H32="",F32,H32)+Profiles!$B$10*IF(I32="",F32,I32))+Profiles!$C$5*G32)/1000000+Profiles!$D$5*IF(J32="",0,J32) | N32: =K32+L32+M32 | O32: =3*N32
A33: 32 | B33: google/gemini-3.5-flash-lite | C33: 2026-07-21 | D33: Flash Lite line (3.5 is its newest) | F33: 0.3 | G33: 2.5 | H33: 0.03 | I33: 0.083333333 | J33: 3e-07 | K33: =(Profiles!$B$3*(Profiles!$B$9*F33+Profiles!$B$8*IF(H33="",F33,H33)+Profiles!$B$10*IF(I33="",F33,I33))+Profiles!$C$3*G33)/1000000+Profiles!$D$3*IF(J33="",0,J33) | L33: =(Profiles!$B$4*(Profiles!$B$9*F33+Profiles!$B$8*IF(H33="",F33,H33)+Profiles!$B$10*IF(I33="",F33,I33))+Profiles!$C$4*G33)/1000000+Profiles!$D$4*IF(J33="",0,J33) | M33: =(Profiles!$B$5*(Profiles!$B$9*F33+Profiles!$B$8*IF(H33="",F33,H33)+Profiles!$B$10*IF(I33="",F33,I33))+Profiles!$C$5*G33)/1000000+Profiles!$D$5*IF(J33="",0,J33) | N33: =K33+L33+M33 | O33: =3*N33
A34: 33 | B34: deepseek/deepseek-v4-flash-vision-exp | C34: 2026-08-21 | F34: 0.44 | G34: 1.32 | H34: 0.014 | K34: =(Profiles!$B$3*(Profiles!$B$9*F34+Profiles!$B$8*IF(H34="",F34,H34)+Profiles!$B$10*IF(I34="",F34,I34))+Profiles!$C$3*G34)/1000000+Profiles!$D$3*IF(J34="",0,J34) | L34: =(Profiles!$B$4*(Profiles!$B$9*F34+Profiles!$B$8*IF(H34="",F34,H34)+Profiles!$B$10*IF(I34="",F34,I34))+Profiles!$C$4*G34)/1000000+Profiles!$D$4*IF(J34="",0,J34) | M34: =(Profiles!$B$5*(Profiles!$B$9*F34+Profiles!$B$8*IF(H34="",F34,H34)+Profiles!$B$10*IF(I34="",F34,I34))+Profiles!$C$5*G34)/1000000+Profiles!$D$5*IF(J34="",0,J34) | N34: =K34+L34+M34 | O34: =3*N34
A35: 34 | B35: qwen/qwen3.6-35b-a3b | C35: 2026-04-27 | F35: 0.15 | G35: 1 | H35: 0.05 | K35: =(Profiles!$B$3*(Profiles!$B$9*F35+Profiles!$B$8*IF(H35="",F35,H35)+Profiles!$B$10*IF(I35="",F35,I35))+Profiles!$C$3*G35)/1000000+Profiles!$D$3*IF(J35="",0,J35) | L35: =(Profiles!$B$4*(Profiles!$B$9*F35+Profiles!$B$8*IF(H35="",F35,H35)+Profiles!$B$10*IF(I35="",F35,I35))+Profiles!$C$4*G35)/1000000+Profiles!$D$4*IF(J35="",0,J35) | M35: =(Profiles!$B$5*(Profiles!$B$9*F35+Profiles!$B$8*IF(H35="",F35,H35)+Profiles!$B$10*IF(I35="",F35,I35))+Profiles!$C$5*G35)/1000000+Profiles!$D$5*IF(J35="",0,J35) | N35: =K35+L35+M35 | O35: =3*N35
A36: 35 | B36: stepfun/step-3.7-flash | C36: 2026-05-28 | F36: 0.2 | G36: 1.15 | H36: 0.04 | K36: =(Profiles!$B$3*(Profiles!$B$9*F36+Profiles!$B$8*IF(H36="",F36,H36)+Profiles!$B$10*IF(I36="",F36,I36))+Profiles!$C$3*G36)/1000000+Profiles!$D$3*IF(J36="",0,J36) | L36: =(Profiles!$B$4*(Profiles!$B$9*F36+Profiles!$B$8*IF(H36="",F36,H36)+Profiles!$B$10*IF(I36="",F36,I36))+Profiles!$C$4*G36)/1000000+Profiles!$D$4*IF(J36="",0,J36) | M36: =(Profiles!$B$5*(Profiles!$B$9*F36+Profiles!$B$8*IF(H36="",F36,H36)+Profiles!$B$10*IF(I36="",F36,I36))+Profiles!$C$5*G36)/1000000+Profiles!$D$5*IF(J36="",0,J36) | N36: =K36+L36+M36 | O36: =3*N36
A37: 36 | B37: xiaomi/mimo-v2.6-pro | C37: 2026-09-21 | E37: yes | F37: 0.435 | G37: 0.87 | H37: 0.0036 | K37: =(Profiles!$B$3*(Profiles!$B$9*F37+Profiles!$B$8*IF(H37="",F37,H37)+Profiles!$B$10*IF(I37="",F37,I37))+Profiles!$C$3*G37)/1000000+Profiles!$D$3*IF(J37="",0,J37) | L37: =(Profiles!$B$4*(Profiles!$B$9*F37+Profiles!$B$8*IF(H37="",F37,H37)+Profiles!$B$10*IF(I37="",F37,I37))+Profiles!$C$4*G37)/1000000+Profiles!$D$4*IF(J37="",0,J37) | M37: =(Profiles!$B$5*(Profiles!$B$9*F37+Profiles!$B$8*IF(H37="",F37,H37)+Profiles!$B$10*IF(I37="",F37,I37))+Profiles!$C$5*G37)/1000000+Profiles!$D$5*IF(J37="",0,J37) | N37: =K37+L37+M37 | O37: =3*N37
A38: 37 | B38: google/gemma-4-31b-it | C38: 2026-04-02 | F38: 0.09 | G38: 0.34 | H38: 0.05 | K38: =(Profiles!$B$3*(Profiles!$B$9*F38+Profiles!$B$8*IF(H38="",F38,H38)+Profiles!$B$10*IF(I38="",F38,I38))+Profiles!$C$3*G38)/1000000+Profiles!$D$3*IF(J38="",0,J38) | L38: =(Profiles!$B$4*(Profiles!$B$9*F38+Profiles!$B$8*IF(H38="",F38,H38)+Profiles!$B$10*IF(I38="",F38,I38))+Profiles!$C$4*G38)/1000000+Profiles!$D$4*IF(J38="",0,J38) | M38: =(Profiles!$B$5*(Profiles!$B$9*F38+Profiles!$B$8*IF(H38="",F38,H38)+Profiles!$B$10*IF(I38="",F38,I38))+Profiles!$C$5*G38)/1000000+Profiles!$D$5*IF(J38="",0,J38) | N38: =K38+L38+M38 | O38: =3*N38
A39: 38 | B39: google/gemma-4-26b-a4b-it | C39: 2026-04-03 | F39: 0.09 | G39: 0.3 | H39: 0.05 | K39: =(Profiles!$B$3*(Profiles!$B$9*F39+Profiles!$B$8*IF(H39="",F39,H39)+Profiles!$B$10*IF(I39="",F39,I39))+Profiles!$C$3*G39)/1000000+Profiles!$D$3*IF(J39="",0,J39) | L39: =(Profiles!$B$4*(Profiles!$B$9*F39+Profiles!$B$8*IF(H39="",F39,H39)+Profiles!$B$10*IF(I39="",F39,I39))+Profiles!$C$4*G39)/1000000+Profiles!$D$4*IF(J39="",0,J39) | M39: =(Profiles!$B$5*(Profiles!$B$9*F39+Profiles!$B$8*IF(H39="",F39,H39)+Profiles!$B$10*IF(I39="",F39,I39))+Profiles!$C$5*G39)/1000000+Profiles!$D$5*IF(J39="",0,J39) | N39: =K39+L39+M39 | O39: =3*N39
A40: 39 | B40: z-ai/glm-5.3-flash | C40: 2026-08-26 | E40: yes | F40: 0.15 | G40: 0.5 | H40: 0.03 | K40: =(Profiles!$B$3*(Profiles!$B$9*F40+Profiles!$B$8*IF(H40="",F40,H40)+Profiles!$B$10*IF(I40="",F40,I40))+Profiles!$C$3*G40)/1000000+Profiles!$D$3*IF(J40="",0,J40) | L40: =(Profiles!$B$4*(Profiles!$B$9*F40+Profiles!$B$8*IF(H40="",F40,H40)+Profiles!$B$10*IF(I40="",F40,I40))+Profiles!$C$4*G40)/1000000+Profiles!$D$4*IF(J40="",0,J40) | M40: =(Profiles!$B$5*(Profiles!$B$9*F40+Profiles!$B$8*IF(H40="",F40,H40)+Profiles!$B$10*IF(I40="",F40,I40))+Profiles!$C$5*G40)/1000000+Profiles!$D$5*IF(J40="",0,J40) | N40: =K40+L40+M40 | O40: =3*N40
...

Sheet Present & past (156)
A1: # | B1: model | C1: released | D1: note | E1: painted with it | F1: $/M input | G1: $/M output | H1: $/M cache read | I1: $/M cache write | J1: $/image | K1: light $ | L1: typical $ | M1: heavy $ | N1: one pass $ | O1: three passes $
A2: 1 | B2: perceptron/perceptron-mk1.5 | C2: 2026-09-25 | F2: 0.15 | G2: 1.5 | K2: =(Profiles!$B$3*(Profiles!$B$9*F2+Profiles!$B$8*IF(H2="",F2,H2)+Profiles!$B$10*IF(I2="",F2,I2))+Profiles!$C$3*G2)/1000000+Profiles!$D$3*IF(J2="",0,J2) | L2: =(Profiles!$B$4*(Profiles!$B$9*F2+Profiles!$B$8*IF(H2="",F2,H2)+Profiles!$B$10*IF(I2="",F2,I2))+Profiles!$C$4*G2)/1000000+Profiles!$D$4*IF(J2="",0,J2) | M2: =(Profiles!$B$5*(Profiles!$B$9*F2+Profiles!$B$8*IF(H2="",F2,H2)+Profiles!$B$10*IF(I2="",F2,I2))+Profiles!$C$5*G2)/1000000+Profiles!$D$5*IF(J2="",0,J2) | N2: =K2+L2+M2 | O2: =3*N2
A3: 2 | B3: fireworks/ember-1 | C3: 2026-09-24 | D3: Kimi K3 fine-tune with shorter reasoning (likely cheaper than shown) | F3: 3 | G3: 15 | H3: 0.3 | K3: =(Profiles!$B$3*(Profiles!$B$9*F3+Profiles!$B$8*IF(H3="",F3,H3)+Profiles!$B$10*IF(I3="",F3,I3))+Profiles!$C$3*G3)/1000000+Profiles!$D$3*IF(J3="",0,J3) | L3: =(Profiles!$B$4*(Profiles!$B$9*F3+Profiles!$B$8*IF(H3="",F3,H3)+Profiles!$B$10*IF(I3="",F3,I3))+Profiles!$C$4*G3)/1000000+Profiles!$D$4*IF(J3="",0,J3) | M3: =(Profiles!$B$5*(Profiles!$B$9*F3+Profiles!$B$8*IF(H3="",F3,H3)+Profiles!$B$10*IF(I3="",F3,I3))+Profiles!$C$5*G3)/1000000+Profiles!$D$5*IF(J3="",0,J3) | N3: =K3+L3+M3 | O3: =3*N3
A4: 3 | B4: qwen/qwen3.8-max-prime | C4: 2026-09-23 | F4: 4 | G4: 12 | H4: 0.5 | K4: =(Profiles!$B$3*(Profiles!$B$9*F4+Profiles!$B$8*IF(H4="",F4,H4)+Profiles!$B$10*IF(I4="",F4,I4))+Profiles!$C$3*G4)/1000000+Profiles!$D$3*IF(J4="",0,J4) | L4: =(Profiles!$B$4*(Profiles!$B$9*F4+Profiles!$B$8*IF(H4="",F4,H4)+Profiles!$B$10*IF(I4="",F4,I4))+Profiles!$C$4*G4)/1000000+Profiles!$D$4*IF(J4="",0,J4) | M4: =(Profiles!$B$5*(Profiles!$B$9*F4+Profiles!$B$8*IF(H4="",F4,H4)+Profiles!$B$10*IF(I4="",F4,I4))+Profiles!$C$5*G4)/1000000+Profiles!$D$5*IF(J4="",0,J4) | N4: =K4+L4+M4 | O4: =3*N4
A5: 4 | B5: stealth/space-bunny-alpha | C5: 2026-09-23 | D5: free (stealth) | E5: yes | F5: 0 | G5: 0 | K5: =(Profiles!$B$3*(Profiles!$B$9*F5+Profiles!$B$8*IF(H5="",F5,H5)+Profiles!$B$10*IF(I5="",F5,I5))+Profiles!$C$3*G5)/1000000+Profiles!$D$3*IF(J5="",0,J5) | L5: =(Profiles!$B$4*(Profiles!$B$9*F5+Profiles!$B$8*IF(H5="",F5,H5)+Profiles!$B$10*IF(I5="",F5,I5))+Profiles!$C$4*G5)/1000000+Profiles!$D$4*IF(J5="",0,J5) | M5: =(Profiles!$B$5*(Profiles!$B$9*F5+Profiles!$B$8*IF(H5="",F5,H5)+Profiles!$B$10*IF(I5="",F5,I5))+Profiles!$C$5*G5)/1000000+Profiles!$D$5*IF(J5="",0,J5) | N5: =K5+L5+M5 | O5: =3*N5
A6: 5 | B6: cohere/command-a-plus | C6: 2026-09-22 | F6: 0.3 | G6: 1.5 | H6: 0.15 | K6: =(Profiles!$B$3*(Profiles!$B$9*F6+Profiles!$B$8*IF(H6="",F6,H6)+Profiles!$B$10*IF(I6="",F6,I6))+Profiles!$C$3*G6)/1000000+Profiles!$D$3*IF(J6="",0,J6) | L6: =(Profiles!$B$4*(Profiles!$B$9*F6+Profiles!$B$8*IF(H6="",F6,H6)+Profiles!$B$10*IF(I6="",F6,I6))+Profiles!$C$4*G6)/1000000+Profiles!$D$4*IF(J6="",0,J6) | M6: =(Profiles!$B$5*(Profiles!$B$9*F6+Profiles!$B$8*IF(H6="",F6,H6)+Profiles!$B$10*IF(I6="",F6,I6))+Profiles!$C$5*G6)/1000000+Profiles!$D$5*IF(J6="",0,J6) | N6: =K6+L6+M6 | O6: =3*N6
A7: 6 | B7: openai/gpt-6-luna | C7: 2026-09-22 | E7: yes | F7: 0.1 | G7: 0.5 | H7: 0.01 | I7: 0.125 | K7: =(Profiles!$B$3*(Profiles!$B$9*F7+Profiles!$B$8*IF(H7="",F7,H7)+Profiles!$B$10*IF(I7="",F7,I7))+Profiles!$C$3*G7)/1000000+Profiles!$D$3*IF(J7="",0,J7) | L7: =(Profiles!$B$4*(Profiles!$B$9*F7+Profiles!$B$8*IF(H7="",F7,H7)+Profiles!$B$10*IF(I7="",F7,I7))+Profiles!$C$4*G7)/1000000+Profiles!$D$4*IF(J7="",0,J7) | M7: =(Profiles!$B$5*(Profiles!$B$9*F7+Profiles!$B$8*IF(H7="",F7,H7)+Profiles!$B$10*IF(I7="",F7,I7))+Profiles!$C$5*G7)/1000000+Profiles!$D$5*IF(J7="",0,J7) | N7: =K7+L7+M7 | O7: =3*N7
A8: 7 | B8: openai/gpt-6-sol | C8: 2026-09-22 | F8: 2 | G8: 10 | H8: 0.2 | I8: 2.5 | K8: =(Profiles!$B$3*(Profiles!$B$9*F8+Profiles!$B$8*IF(H8="",F8,H8)+Profiles!$B$10*IF(I8="",F8,I8))+Profiles!$C$3*G8)/1000000+Profiles!$D$3*IF(J8="",0,J8) | L8: =(Profiles!$B$4*(Profiles!$B$9*F8+Profiles!$B$8*IF(H8="",F8,H8)+Profiles!$B$10*IF(I8="",F8,I8))+Profiles!$C$4*G8)/1000000+Profiles!$D$4*IF(J8="",0,J8) | M8: =(Profiles!$B$5*(Profiles!$B$9*F8+Profiles!$B$8*IF(H8="",F8,H8)+Profiles!$B$10*IF(I8="",F8,I8))+Profiles!$C$5*G8)/1000000+Profiles!$D$5*IF(J8="",0,J8) | N8: =K8+L8+M8 | O8: =3*N8
A9: 8 | B9: anthropic/claude-opus-5.5 | C9: 2026-09-22 | E9: yes | F9: 4 | G9: 20 | H9: 0.2 | I9: 5 | K9: =(Profiles!$B$3*(Profiles!$B$9*F9+Profiles!$B$8*IF(H9="",F9,H9)+Profiles!$B$10*IF(I9="",F9,I9))+Profiles!$C$3*G9)/1000000+Profiles!$D$3*IF(J9="",0,J9) | L9: =(Profiles!$B$4*(Profiles!$B$9*F9+Profiles!$B$8*IF(H9="",F9,H9)+Profiles!$B$10*IF(I9="",F9,I9))+Profiles!$C$4*G9)/1000000+Profiles!$D$4*IF(J9="",0,J9) | M9: =(Profiles!$B$5*(Profiles!$B$9*F9+Profiles!$B$8*IF(H9="",F9,H9)+Profiles!$B$10*IF(I9="",F9,I9))+Profiles!$C$5*G9)/1000000+Profiles!$D$5*IF(J9="",0,J9) | N9: =K9+L9+M9 | O9: =3*N9
A10: 9 | B10: xiaomi/mimo-v2.6-pro-ultraspeed | C10: 2026-09-21 | F10: 4.35 | G10: 8.7 | H10: 0.036 | K10: =(Profiles!$B$3*(Profiles!$B$9*F10+Profiles!$B$8*IF(H10="",F10,H10)+Profiles!$B$10*IF(I10="",F10,I10))+Profiles!$C$3*G10)/1000000+Profiles!$D$3*IF(J10="",0,J10) | L10: =(Profiles!$B$4*(Profiles!$B$9*F10+Profiles!$B$8*IF(H10="",F10,H10)+Profiles!$B$10*IF(I10="",F10,I10))+Profiles!$C$4*G10)/1000000+Profiles!$D$4*IF(J10="",0,J10) | M10: =(Profiles!$B$5*(Profiles!$B$9*F10+Profiles!$B$8*IF(H10="",F10,H10)+Profiles!$B$10*IF(I10="",F10,I10))+Profiles!$C$5*G10)/1000000+Profiles!$D$5*IF(J10="",0,J10) | N10: =K10+L10+M10 | O10: =3*N10
A11: 10 | B11: xiaomi/mimo-v2.6-flash | C11: 2026-09-21 | F11: 0.14 | G11: 0.28 | H11: 0.0028 | K11: =(Profiles!$B$3*(Profiles!$B$9*F11+Profiles!$B$8*IF(H11="",F11,H11)+Profiles!$B$10*IF(I11="",F11,I11))+Profiles!$C$3*G11)/1000000+Profiles!$D$3*IF(J11="",0,J11) | L11: =(Profiles!$B$4*(Profiles!$B$9*F11+Profiles!$B$8*IF(H11="",F11,H11)+Profiles!$B$10*IF(I11="",F11,I11))+Profiles!$C$4*G11)/1000000+Profiles!$D$4*IF(J11="",0,J11) | M11: =(Profiles!$B$5*(Profiles!$B$9*F11+Profiles!$B$8*IF(H11="",F11,H11)+Profiles!$B$10*IF(I11="",F11,I11))+Profiles!$C$5*G11)/1000000+Profiles!$D$5*IF(J11="",0,J11) | N11: =K11+L11+M11 | O11: =3*N11
A12: 11 | B12: xiaomi/mimo-v2.6-pro | C12: 2026-09-21 | E12: yes | F12: 0.435 | G12: 0.87 | H12: 0.0036 | K12: =(Profiles!$B$3*(Profiles!$B$9*F12+Profiles!$B$8*IF(H12="",F12,H12)+Profiles!$B$10*IF(I12="",F12,I12))+Profiles!$C$3*G12)/1000000+Profiles!$D$3*IF(J12="",0,J12) | L12: =(Profiles!$B$4*(Profiles!$B$9*F12+Profiles!$B$8*IF(H12="",F12,H12)+Profiles!$B$10*IF(I12="",F12,I12))+Profiles!$C$4*G12)/1000000+Profiles!$D$4*IF(J12="",0,J12) | M12: =(Profiles!$B$5*(Profiles!$B$9*F12+Profiles!$B$8*IF(H12="",F12,H12)+Profiles!$B$10*IF(I12="",F12,I12))+Profiles!$C$5*G12)/1000000+Profiles!$D$5*IF(J12="",0,J12) | N12: =K12+L12+M12 | O12: =3*N12
A13: 12 | B13: x-ai/grok-4.7 | C13: 2026-09-21 | F13: 1.6 | G13: 4.8 | H13: 0.4 | K13: =(Profiles!$B$3*(Profiles!$B$9*F13+Profiles!$B$8*IF(H13="",F13,H13)+Profiles!$B$10*IF(I13="",F13,I13))+Profiles!$C$3*G13)/1000000+Profiles!$D$3*IF(J13="",0,J13) | L13: =(Profiles!$B$4*(Profiles!$B$9*F13+Profiles!$B$8*IF(H13="",F13,H13)+Profiles!$B$10*IF(I13="",F13,I13))+Profiles!$C$4*G13)/1000000+Profiles!$D$4*IF(J13="",0,J13) | M13: =(Profiles!$B$5*(Profiles!$B$9*F13+Profiles!$B$8*IF(H13="",F13,H13)+Profiles!$B$10*IF(I13="",F13,I13))+Profiles!$C$5*G13)/1000000+Profiles!$D$5*IF(J13="",0,J13) | N13: =K13+L13+M13 | O13: =3*N13
A14: 13 | B14: qwen/qwen3.8-omni-flash | C14: 2026-09-21 | F14: 0.15 | G14: 0.47 | H14: 0.016 | K14: =(Profiles!$B$3*(Profiles!$B$9*F14+Profiles!$B$8*IF(H14="",F14,H14)+Profiles!$B$10*IF(I14="",F14,I14))+Profiles!$C$3*G14)/1000000+Profiles!$D$3*IF(J14="",0,J14) | L14: =(Profiles!$B$4*(Profiles!$B$9*F14+Profiles!$B$8*IF(H14="",F14,H14)+Profiles!$B$10*IF(I14="",F14,I14))+Profiles!$C$4*G14)/1000000+Profiles!$D$4*IF(J14="",0,J14) | M14: =(Profiles!$B$5*(Profiles!$B$9*F14+Profiles!$B$8*IF(H14="",F14,H14)+Profiles!$B$10*IF(I14="",F14,I14))+Profiles!$C$5*G14)/1000000+Profiles!$D$5*IF(J14="",0,J14) | N14: =K14+L14+M14 | O14: =3*N14
A15: 14 | B15: prism-ml/ternary-bonsai-2-27b | C15: 2026-09-18 | F15: 0.075 | G15: 0.5 | K15: =(Profiles!$B$3*(Profiles!$B$9*F15+Profiles!$B$8*IF(H15="",F15,H15)+Profiles!$B$10*IF(I15="",F15,I15))+Profiles!$C$3*G15)/1000000+Profiles!$D$3*IF(J15="",0,J15) | L15: =(Profiles!$B$4*(Profiles!$B$9*F15+Profiles!$B$8*IF(H15="",F15,H15)+Profiles!$B$10*IF(I15="",F15,I15))+Profiles!$C$4*G15)/1000000+Profiles!$D$4*IF(J15="",0,J15) | M15: =(Profiles!$B$5*(Profiles!$B$9*F15+Profiles!$B$8*IF(H15="",F15,H15)+Profiles!$B$10*IF(I15="",F15,I15))+Profiles!$C$5*G15)/1000000+Profiles!$D$5*IF(J15="",0,J15) | N15: =K15+L15+M15 | O15: =3*N15
A16: 15 | B16: z-ai/glm-5.3-flashx | C16: 2026-09-18 | F16: 0.37 | G16: 1.25 | H16: 0.09 | K16: =(Profiles!$B$3*(Profiles!$B$9*F16+Profiles!$B$8*IF(H16="",F16,H16)+Profiles!$B$10*IF(I16="",F16,I16))+Profiles!$C$3*G16)/1000000+Profiles!$D$3*IF(J16="",0,J16) | L16: =(Profiles!$B$4*(Profiles!$B$9*F16+Profiles!$B$8*IF(H16="",F16,H16)+Profiles!$B$10*IF(I16="",F16,I16))+Profiles!$C$4*G16)/1000000+Profiles!$D$4*IF(J16="",0,J16) | M16: =(Profiles!$B$5*(Profiles!$B$9*F16+Profiles!$B$8*IF(H16="",F16,H16)+Profiles!$B$10*IF(I16="",F16,I16))+Profiles!$C$5*G16)/1000000+Profiles!$D$5*IF(J16="",0,J16) | N16: =K16+L16+M16 | O16: =3*N16
A17: 16 | B17: unbiased/pareto | C17: 2026-09-18 | D17: ensemble (several unnamed models per request): kept on purpose | F17: 2.5 | G17: 7.5 | H17: 0.25 | K17: =(Profiles!$B$3*(Profiles!$B$9*F17+Profiles!$B$8*IF(H17="",F17,H17)+Profiles!$B$10*IF(I17="",F17,I17))+Profiles!$C$3*G17)/1000000+Profiles!$D$3*IF(J17="",0,J17) | L17: =(Profiles!$B$4*(Profiles!$B$9*F17+Profiles!$B$8*IF(H17="",F17,H17)+Profiles!$B$10*IF(I17="",F17,I17))+Profiles!$C$4*G17)/1000000+Profiles!$D$4*IF(J17="",0,J17) | M17: =(Profiles!$B$5*(Profiles!$B$9*F17+Profiles!$B$8*IF(H17="",F17,H17)+Profiles!$B$10*IF(I17="",F17,I17))+Profiles!$C$5*G17)/1000000+Profiles!$D$5*IF(J17="",0,J17) | N17: =K17+L17+M17 | O17: =3*N17
A18: 17 | B18: inclusionai/ling-3.0-flash-vl | C18: 2026-09-10 | F18: 0.021 | G18: 0.0616 | H18: 0.0042 | K18: =(Profiles!$B$3*(Profiles!$B$9*F18+Profiles!$B$8*IF(H18="",F18,H18)+Profiles!$B$10*IF(I18="",F18,I18))+Profiles!$C$3*G18)/1000000+Profiles!$D$3*IF(J18="",0,J18) | L18: =(Profiles!$B$4*(Profiles!$B$9*F18+Profiles!$B$8*IF(H18="",F18,H18)+Profiles!$B$10*IF(I18="",F18,I18))+Profiles!$C$4*G18)/1000000+Profiles!$D$4*IF(J18="",0,J18) | M18: =(Profiles!$B$5*(Profiles!$B$9*F18+Profiles!$B$8*IF(H18="",F18,H18)+Profiles!$B$10*IF(I18="",F18,I18))+Profiles!$C$5*G18)/1000000+Profiles!$D$5*IF(J18="",0,J18) | N18: =K18+L18+M18 | O18: =3*N18
A19: 18 | B19: deepseek/deepseek-v4.1-flash | C19: 2026-09-10 | E19: yes | F19: 0.035 | G19: 0.29 | H19: 0.001 | K19: =(Profiles!$B$3*(Profiles!$B$9*F19+Profiles!$B$8*IF(H19="",F19,H19)+Profiles!$B$10*IF(I19="",F19,I19))+Profiles!$C$3*G19)/1000000+Profiles!$D$3*IF(J19="",0,J19) | L19: =(Profiles!$B$4*(Profiles!$B$9*F19+Profiles!$B$8*IF(H19="",F19,H19)+Profiles!$B$10*IF(I19="",F19,I19))+Profiles!$C$4*G19)/1000000+Profiles!$D$4*IF(J19="",0,J19) | M19: =(Profiles!$B$5*(Profiles!$B$9*F19+Profiles!$B$8*IF(H19="",F19,H19)+Profiles!$B$10*IF(I19="",F19,I19))+Profiles!$C$5*G19)/1000000+Profiles!$D$5*IF(J19="",0,J19) | N19: =K19+L19+M19 | O19: =3*N19
A20: 19 | B20: openai/gpt-6-astra | C20: 2026-09-04 | E20: yes | F20: 10 | G20: 50 | H20: 1 | I20: 12.5 | K20: =(Profiles!$B$3*(Profiles!$B$9*F20+Profiles!$B$8*IF(H20="",F20,H20)+Profiles!$B$10*IF(I20="",F20,I20))+Profiles!$C$3*G20)/1000000+Profiles!$D$3*IF(J20="",0,J20) | L20: =(Profiles!$B$4*(Profiles!$B$9*F20+Profiles!$B$8*IF(H20="",F20,H20)+Profiles!$B$10*IF(I20="",F20,I20))+Profiles!$C$4*G20)/1000000+Profiles!$D$4*IF(J20="",0,J20) | M20: =(Profiles!$B$5*(Profiles!$B$9*F20+Profiles!$B$8*IF(H20="",F20,H20)+Profiles!$B$10*IF(I20="",F20,I20))+Profiles!$C$5*G20)/1000000+Profiles!$D$5*IF(J20="",0,J20) | N20: =K20+L20+M20 | O20: =3*N20
A21: 20 | B21: qwen/qwen3.8-max-0902 | C21: 2026-09-03 | F21: 2 | G21: 6 | H21: 0.25 | I21: 2.5 | K21: =(Profiles!$B$3*(Profiles!$B$9*F21+Profiles!$B$8*IF(H21="",F21,H21)+Profiles!$B$10*IF(I21="",F21,I21))+Profiles!$C$3*G21)/1000000+Profiles!$D$3*IF(J21="",0,J21) | L21: =(Profiles!$B$4*(Profiles!$B$9*F21+Profiles!$B$8*IF(H21="",F21,H21)+Profiles!$B$10*IF(I21="",F21,I21))+Profiles!$C$4*G21)/1000000+Profiles!$D$4*IF(J21="",0,J21) | M21: =(Profiles!$B$5*(Profiles!$B$9*F21+Profiles!$B$8*IF(H21="",F21,H21)+Profiles!$B$10*IF(I21="",F21,I21))+Profiles!$C$5*G21)/1000000+Profiles!$D$5*IF(J21="",0,J21) | N21: =K21+L21+M21 | O21: =3*N21
A22: 21 | B22: meta/muse-spark-1.3-contributor | C22: 2026-09-02 | D22: cheap contributor tier (check its data terms) | F22: 0.1 | G22: 0.2 | H22: 0.002 | K22: =(Profiles!$B$3*(Profiles!$B$9*F22+Profiles!$B$8*IF(H22="",F22,H22)+Profiles!$B$10*IF(I22="",F22,I22))+Profiles!$C$3*G22)/1000000+Profiles!$D$3*IF(J22="",0,J22) | L22: =(Profiles!$B$4*(Profiles!$B$9*F22+Profiles!$B$8*IF(H22="",F22,H22)+Profiles!$B$10*IF(I22="",F22,I22))+Profiles!$C$4*G22)/1000000+Profiles!$D$4*IF(J22="",0,J22) | M22: =(Profiles!$B$5*(Profiles!$B$9*F22+Profiles!$B$8*IF(H22="",F22,H22)+Profiles!$B$10*IF(I22="",F22,I22))+Profiles!$C$5*G22)/1000000+Profiles!$D$5*IF(J22="",0,J22) | N22: =K22+L22+M22 | O22: =3*N22
A23: 22 | B23: meta/muse-spark-1.3 | C23: 2026-09-02 | E23: yes | F23: 1.25 | G23: 4.25 | H23: 0.15 | K23: =(Profiles!$B$3*(Profiles!$B$9*F23+Profiles!$B$8*IF(H23="",F23,H23)+Profiles!$B$10*IF(I23="",F23,I23))+Profiles!$C$3*G23)/1000000+Profiles!$D$3*IF(J23="",0,J23) | L23: =(Profiles!$B$4*(Profiles!$B$9*F23+Profiles!$B$8*IF(H23="",F23,H23)+Profiles!$B$10*IF(I23="",F23,I23))+Profiles!$C$4*G23)/1000000+Profiles!$D$4*IF(J23="",0,J23) | M23: =(Profiles!$B$5*(Profiles!$B$9*F23+Profiles!$B$8*IF(H23="",F23,H23)+Profiles!$B$10*IF(I23="",F23,I23))+Profiles!$C$5*G23)/1000000+Profiles!$D$5*IF(J23="",0,J23) | N23: =K23+L23+M23 | O23: =3*N23
A24: 23 | B24: google/gemini-3.8-flash | C24: 2026-09-02 | E24: yes | F24: 0.75 | G24: 3.75 | H24: 0.075 | I24: 0.041666667 | J24: 7.5e-07 | K24: =(Profiles!$B$3*(Profiles!$B$9*F24+Profiles!$B$8*IF(H24="",F24,H24)+Profiles!$B$10*IF(I24="",F24,I24))+Profiles!$C$3*G24)/1000000+Profiles!$D$3*IF(J24="",0,J24) | L24: =(Profiles!$B$4*(Profiles!$B$9*F24+Profiles!$B$8*IF(H24="",F24,H24)+Profiles!$B$10*IF(I24="",F24,I24))+Profiles!$C$4*G24)/1000000+Profiles!$D$4*IF(J24="",0,J24) | M24: =(Profiles!$B$5*(Profiles!$B$9*F24+Profiles!$B$8*IF(H24="",F24,H24)+Profiles!$B$10*IF(I24="",F24,I24))+Profiles!$C$5*G24)/1000000+Profiles!$D$5*IF(J24="",0,J24) | N24: =K24+L24+M24 | O24: =3*N24
A25: 24 | B25: anthropic/claude-fable-5.1 | C25: 2026-09-01 | E25: yes | F25: 10 | G25: 50 | H25: 0.25 | I25: 12.5 | K25: =(Profiles!$B$3*(Profiles!$B$9*F25+Profiles!$B$8*IF(H25="",F25,H25)+Profiles!$B$10*IF(I25="",F25,I25))+Profiles!$C$3*G25)/1000000+Profiles!$D$3*IF(J25="",0,J25) | L25: =(Profiles!$B$4*(Profiles!$B$9*F25+Profiles!$B$8*IF(H25="",F25,H25)+Profiles!$B$10*IF(I25="",F25,I25))+Profiles!$C$4*G25)/1000000+Profiles!$D$4*IF(J25="",0,J25) | M25: =(Profiles!$B$5*(Profiles!$B$9*F25+Profiles!$B$8*IF(H25="",F25,H25)+Profiles!$B$10*IF(I25="",F25,I25))+Profiles!$C$5*G25)/1000000+Profiles!$D$5*IF(J25="",0,J25) | N25: =K25+L25+M25 | O25: =3*N25
A26: 25 | B26: qwen/qwen3.8-flash | C26: 2026-08-26 | F26: 0.15 | G26: 0.47 | H26: 0.016 | I26: 0.2 | K26: =(Profiles!$B$3*(Profiles!$B$9*F26+Profiles!$B$8*IF(H26="",F26,H26)+Profiles!$B$10*IF(I26="",F26,I26))+Profiles!$C$3*G26)/1000000+Profiles!$D$3*IF(J26="",0,J26) | L26: =(Profiles!$B$4*(Profiles!$B$9*F26+Profiles!$B$8*IF(H26="",F26,H26)+Profiles!$B$10*IF(I26="",F26,I26))+Profiles!$C$4*G26)/1000000+Profiles!$D$4*IF(J26="",0,J26) | M26: =(Profiles!$B$5*(Profiles!$B$9*F26+Profiles!$B$8*IF(H26="",F26,H26)+Profiles!$B$10*IF(I26="",F26,I26))+Profiles!$C$5*G26)/1000000+Profiles!$D$5*IF(J26="",0,J26) | N26: =K26+L26+M26 | O26: =3*N26
A27: 26 | B27: z-ai/glm-5.3-flash | C27: 2026-08-26 | E27: yes | F27: 0.15 | G27: 0.5 | H27: 0.03 | K27: =(Profiles!$B$3*(Profiles!$B$9*F27+Profiles!$B$8*IF(H27="",F27,H27)+Profiles!$B$10*IF(I27="",F27,I27))+Profiles!$C$3*G27)/1000000+Profiles!$D$3*IF(J27="",0,J27) | L27: =(Profiles!$B$4*(Profiles!$B$9*F27+Profiles!$B$8*IF(H27="",F27,H27)+Profiles!$B$10*IF(I27="",F27,I27))+Profiles!$C$4*G27)/1000000+Profiles!$D$4*IF(J27="",0,J27) | M27: =(Profiles!$B$5*(Profiles!$B$9*F27+Profiles!$B$8*IF(H27="",F27,H27)+Profiles!$B$10*IF(I27="",F27,I27))+Profiles!$C$5*G27)/1000000+Profiles!$D$5*IF(J27="",0,J27) | N27: =K27+L27+M27 | O27: =3*N27
A28: 27 | B28: meta/muse-spark-1.2-contributor | C28: 2026-08-21 | F28: 0.1 | G28: 0.2 | H28: 0.002 | K28: =(Profiles!$B$3*(Profiles!$B$9*F28+Profiles!$B$8*IF(H28="",F28,H28)+Profiles!$B$10*IF(I28="",F28,I28))+Profiles!$C$3*G28)/1000000+Profiles!$D$3*IF(J28="",0,J28) | L28: =(Profiles!$B$4*(Profiles!$B$9*F28+Profiles!$B$8*IF(H28="",F28,H28)+Profiles!$B$10*IF(I28="",F28,I28))+Profiles!$C$4*G28)/1000000+Profiles!$D$4*IF(J28="",0,J28) | M28: =(Profiles!$B$5*(Profiles!$B$9*F28+Profiles!$B$8*IF(H28="",F28,H28)+Profiles!$B$10*IF(I28="",F28,I28))+Profiles!$C$5*G28)/1000000+Profiles!$D$5*IF(J28="",0,J28) | N28: =K28+L28+M28 | O28: =3*N28
A29: 28 | B29: deepseek/deepseek-v4-flash-vision-exp | C29: 2026-08-21 | F29: 0.44 | G29: 1.32 | H29: 0.014 | K29: =(Profiles!$B$3*(Profiles!$B$9*F29+Profiles!$B$8*IF(H29="",F29,H29)+Profiles!$B$10*IF(I29="",F29,I29))+Profiles!$C$3*G29)/1000000+Profiles!$D$3*IF(J29="",0,J29) | L29: =(Profiles!$B$4*(Profiles!$B$9*F29+Profiles!$B$8*IF(H29="",F29,H29)+Profiles!$B$10*IF(I29="",F29,I29))+Profiles!$C$4*G29)/1000000+Profiles!$D$4*IF(J29="",0,J29) | M29: =(Profiles!$B$5*(Profiles!$B$9*F29+Profiles!$B$8*IF(H29="",F29,H29)+Profiles!$B$10*IF(I29="",F29,I29))+Profiles!$C$5*G29)/1000000+Profiles!$D$5*IF(J29="",0,J29) | N29: =K29+L29+M29 | O29: =3*N29
A30: 29 | B30: qwen/qwen3.8-27b | C30: 2026-08-14 | F30: 0.42 | G30: 3 | H30: 0.085 | K30: =(Profiles!$B$3*(Profiles!$B$9*F30+Profiles!$B$8*IF(H30="",F30,H30)+Profiles!$B$10*IF(I30="",F30,I30))+Profiles!$C$3*G30)/1000000+Profiles!$D$3*IF(J30="",0,J30) | L30: =(Profiles!$B$4*(Profiles!$B$9*F30+Profiles!$B$8*IF(H30="",F30,H30)+Profiles!$B$10*IF(I30="",F30,I30))+Profiles!$C$4*G30)/1000000+Profiles!$D$4*IF(J30="",0,J30) | M30: =(Profiles!$B$5*(Profiles!$B$9*F30+Profiles!$B$8*IF(H30="",F30,H30)+Profiles!$B$10*IF(I30="",F30,I30))+Profiles!$C$5*G30)/1000000+Profiles!$D$5*IF(J30="",0,J30) | N30: =K30+L30+M30 | O30: =3*N30
A31: 30 | B31: google/gemini-3.7-flash | C31: 2026-08-13 | F31: 0.75 | G31: 3.75 | H31: 0.075 | I31: 0.041666667 | J31: 7.5e-07 | K31: =(Profiles!$B$3*(Profiles!$B$9*F31+Profiles!$B$8*IF(H31="",F31,H31)+Profiles!$B$10*IF(I31="",F31,I31))+Profiles!$C$3*G31)/1000000+Profiles!$D$3*IF(J31="",0,J31) | L31: =(Profiles!$B$4*(Profiles!$B$9*F31+Profiles!$B$8*IF(H31="",F31,H31)+Profiles!$B$10*IF(I31="",F31,I31))+Profiles!$C$4*G31)/1000000+Profiles!$D$4*IF(J31="",0,J31) | M31: =(Profiles!$B$5*(Profiles!$B$9*F31+Profiles!$B$8*IF(H31="",F31,H31)+Profiles!$B$10*IF(I31="",F31,I31))+Profiles!$C$5*G31)/1000000+Profiles!$D$5*IF(J31="",0,J31) | N31: =K31+L31+M31 | O31: =3*N31
A32: 31 | B32: bytedance-seed/seed-2-1-turbo | C32: 2026-08-12 | F32: 0.5 | G32: 2.5 | K32: =(Profiles!$B$3*(Profiles!$B$9*F32+Profiles!$B$8*IF(H32="",F32,H32)+Profiles!$B$10*IF(I32="",F32,I32))+Profiles!$C$3*G32)/1000000+Profiles!$D$3*IF(J32="",0,J32) | L32: =(Profiles!$B$4*(Profiles!$B$9*F32+Profiles!$B$8*IF(H32="",F32,H32)+Profiles!$B$10*IF(I32="",F32,I32))+Profiles!$C$4*G32)/1000000+Profiles!$D$4*IF(J32="",0,J32) | M32: =(Profiles!$B$5*(Profiles!$B$9*F32+Profiles!$B$8*IF(H32="",F32,H32)+Profiles!$B$10*IF(I32="",F32,I32))+Profiles!$C$5*G32)/1000000+Profiles!$D$5*IF(J32="",0,J32) | N32: =K32+L32+M32 | O32: =3*N32
A33: 32 | B33: bytedance-seed/seed-2.0-code | C33: 2026-08-12 | F33: 0.5 | G33: 3 | K33: =(Profiles!$B$3*(Profiles!$B$9*F33+Profiles!$B$8*IF(H33="",F33,H33)+Profiles!$B$10*IF(I33="",F33,I33))+Profiles!$C$3*G33)/1000000+Profiles!$D$3*IF(J33="",0,J33) | L33: =(Profiles!$B$4*(Profiles!$B$9*F33+Profiles!$B$8*IF(H33="",F33,H33)+Profiles!$B$10*IF(I33="",F33,I33))+Profiles!$C$4*G33)/1000000+Profiles!$D$4*IF(J33="",0,J33) | M33: =(Profiles!$B$5*(Profiles!$B$9*F33+Profiles!$B$8*IF(H33="",F33,H33)+Profiles!$B$10*IF(I33="",F33,I33))+Profiles!$C$5*G33)/1000000+Profiles!$D$5*IF(J33="",0,J33) | N33: =K33+L33+M33 | O33: =3*N33
A34: 33 | B34: x-ai/grok-4.6 | C34: 2026-08-12 | F34: 2 | G34: 6 | H34: 0.5 | K34: =(Profiles!$B$3*(Profiles!$B$9*F34+Profiles!$B$8*IF(H34="",F34,H34)+Profiles!$B$10*IF(I34="",F34,I34))+Profiles!$C$3*G34)/1000000+Profiles!$D$3*IF(J34="",0,J34) | L34: =(Profiles!$B$4*(Profiles!$B$9*F34+Profiles!$B$8*IF(H34="",F34,H34)+Profiles!$B$10*IF(I34="",F34,I34))+Profiles!$C$4*G34)/1000000+Profiles!$D$4*IF(J34="",0,J34) | M34: =(Profiles!$B$5*(Profiles!$B$9*F34+Profiles!$B$8*IF(H34="",F34,H34)+Profiles!$B$10*IF(I34="",F34,I34))+Profiles!$C$5*G34)/1000000+Profiles!$D$5*IF(J34="",0,J34) | N34: =K34+L34+M34 | O34: =3*N34
A35: 34 | B35: meta/muse-glimmer-30b | C35: 2026-08-09 | F35: 0.3 | G35: 1.2 | H35: 0.04 | K35: =(Profiles!$B$3*(Profiles!$B$9*F35+Profiles!$B$8*IF(H35="",F35,H35)+Profiles!$B$10*IF(I35="",F35,I35))+Profiles!$C$3*G35)/1000000+Profiles!$D$3*IF(J35="",0,J35) | L35: =(Profiles!$B$4*(Profiles!$B$9*F35+Profiles!$B$8*IF(H35="",F35,H35)+Profiles!$B$10*IF(I35="",F35,I35))+Profiles!$C$4*G35)/1000000+Profiles!$D$4*IF(J35="",0,J35) | M35: =(Profiles!$B$5*(Profiles!$B$9*F35+Profiles!$B$8*IF(H35="",F35,H35)+Profiles!$B$10*IF(I35="",F35,I35))+Profiles!$C$5*G35)/1000000+Profiles!$D$5*IF(J35="",0,J35) | N35: =K35+L35+M35 | O35: =3*N35
A36: 35 | B36: meta/muse-spark-1.2 | C36: 2026-08-05 | F36: 1.25 | G36: 4.25 | H36: 0.15 | K36: =(Profiles!$B$3*(Profiles!$B$9*F36+Profiles!$B$8*IF(H36="",F36,H36)+Profiles!$B$10*IF(I36="",F36,I36))+Profiles!$C$3*G36)/1000000+Profiles!$D$3*IF(J36="",0,J36) | L36: =(Profiles!$B$4*(Profiles!$B$9*F36+Profiles!$B$8*IF(H36="",F36,H36)+Profiles!$B$10*IF(I36="",F36,I36))+Profiles!$C$4*G36)/1000000+Profiles!$D$4*IF(J36="",0,J36) | M36: =(Profiles!$B$5*(Profiles!$B$9*F36+Profiles!$B$8*IF(H36="",F36,H36)+Profiles!$B$10*IF(I36="",F36,I36))+Profiles!$C$5*G36)/1000000+Profiles!$D$5*IF(J36="",0,J36) | N36: =K36+L36+M36 | O36: =3*N36
A37: 36 | B37: thinkingmachines/inkling-small | C37: 2026-07-30 | F37: 0.45 | G37: 1.2 | H37: 0.1 | K37: =(Profiles!$B$3*(Profiles!$B$9*F37+Profiles!$B$8*IF(H37="",F37,H37)+Profiles!$B$10*IF(I37="",F37,I37))+Profiles!$C$3*G37)/1000000+Profiles!$D$3*IF(J37="",0,J37) | L37: =(Profiles!$B$4*(Profiles!$B$9*F37+Profiles!$B$8*IF(H37="",F37,H37)+Profiles!$B$10*IF(I37="",F37,I37))+Profiles!$C$4*G37)/1000000+Profiles!$D$4*IF(J37="",0,J37) | M37: =(Profiles!$B$5*(Profiles!$B$9*F37+Profiles!$B$8*IF(H37="",F37,H37)+Profiles!$B$10*IF(I37="",F37,I37))+Profiles!$C$5*G37)/1000000+Profiles!$D$5*IF(J37="",0,J37) | N37: =K37+L37+M37 | O37: =3*N37
A38: 37 | B38: qwen/qwen3.7-flash | C38: 2026-07-27 | F38: 0.03 | G38: 0.13 | H38: 0.006 | I38: 0.038 | K38: =(Profiles!$B$3*(Profiles!$B$9*F38+Profiles!$B$8*IF(H38="",F38,H38)+Profiles!$B$10*IF(I38="",F38,I38))+Profiles!$C$3*G38)/1000000+Profiles!$D$3*IF(J38="",0,J38) | L38: =(Profiles!$B$4*(Profiles!$B$9*F38+Profiles!$B$8*IF(H38="",F38,H38)+Profiles!$B$10*IF(I38="",F38,I38))+Profiles!$C$4*G38)/1000000+Profiles!$D$4*IF(J38="",0,J38) | M38: =(Profiles!$B$5*(Profiles!$B$9*F38+Profiles!$B$8*IF(H38="",F38,H38)+Profiles!$B$10*IF(I38="",F38,I38))+Profiles!$C$5*G38)/1000000+Profiles!$D$5*IF(J38="",0,J38) | N38: =K38+L38+M38 | O38: =3*N38
A39: 38 | B39: anthropic/claude-opus-5 | C39: 2026-07-24 | F39: 5 | G39: 25 | H39: 0.5 | I39: 6.25 | K39: =(Profiles!$B$3*(Profiles!$B$9*F39+Profiles!$B$8*IF(H39="",F39,H39)+Profiles!$B$10*IF(I39="",F39,I39))+Profiles!$C$3*G39)/1000000+Profiles!$D$3*IF(J39="",0,J39) | L39: =(Profiles!$B$4*(Profiles!$B$9*F39+Profiles!$B$8*IF(H39="",F39,H39)+Profiles!$B$10*IF(I39="",F39,I39))+Profiles!$C$4*G39)/1000000+Profiles!$D$4*IF(J39="",0,J39) | M39: =(Profiles!$B$5*(Profiles!$B$9*F39+Profiles!$B$8*IF(H39="",F39,H39)+Profiles!$B$10*IF(I39="",F39,I39))+Profiles!$C$5*G39)/1000000+Profiles!$D$5*IF(J39="",0,J39) | N39: =K39+L39+M39 | O39: =3*N39
A40: 39 | B40: google/gemini-3.6-flash | C40: 2026-07-21 | F40: 0.75 | G40: 3.75 | H40: 0.075 | I40: 0.041666667 | J40: 7.5e-07 | K40: =(Profiles!$B$3*(Profiles!$B$9*F40+Profiles!$B$8*IF(H40="",F40,H40)+Profiles!$B$10*IF(I40="",F40,I40))+Profiles!$C$3*G40)/1000000+Profiles!$D$3*IF(J40="",0,J40) | L40: =(Profiles!$B$4*(Profiles!$B$9*F40+Profiles!$B$8*IF(H40="",F40,H40)+Profiles!$B$10*IF(I40="",F40,I40))+Profiles!$C$4*G40)/1000000+Profiles!$D$4*IF(J40="",0,J40) | M40: =(Profiles!$B$5*(Profiles!$B$9*F40+Profiles!$B$8*IF(H40="",F40,H40)+Profiles!$B$10*IF(I40="",F40,I40))+Profiles!$C$5*G40)/1000000+Profiles!$D$5*IF(J40="",0,J40) | N40: =K40+L40+M40 | O40: =3*N40
...

Sheet Excluded
A1: model | B1: why
A2: google/gemini-3-pro-image | B2: image-generation model
A3: openai/gpt-5-pro | B3: OpenAI Pro: thinks far longer, costs far more than its list price suggests
A4: openai/gpt-5.2-pro | B4: OpenAI Pro: thinks far longer, costs far more than its list price suggests
A5: openai/gpt-5.4-pro | B5: OpenAI Pro: thinks far longer, costs far more than its list price suggests
A6: openai/gpt-5.5-pro | B6: OpenAI Pro: thinks far longer, costs far more than its list price suggests
A7: openai/gpt-5.6-luna-pro | B7: OpenAI Pro: thinks far longer, costs far more than its list price suggests
A8: openai/gpt-5.6-sol-pro | B8: OpenAI Pro: thinks far longer, costs far more than its list price suggests
A9: openai/gpt-5.6-terra-pro | B9: OpenAI Pro: thinks far longer, costs far more than its list price suggests
A10: openai/gpt-6-astra-pro | B10: OpenAI Pro: thinks far longer, costs far more than its list price suggests
A11: openai/gpt-6-luna-pro | B11: OpenAI Pro: thinks far longer, costs far more than its list price suggests
A12: openai/gpt-6-sol-pro | B12: OpenAI Pro: thinks far longer, costs far more than its list price suggests
... A20: xiaomi/mimo-v2.5 | B20: older MiMo (latest list only)

Sheet Profiles
A1: Token profile of one painting in 4 sittings (edit the blue cells: every cost recalculates)
A2: profile | B2: prompt tokens | C2: output tokens | D2: images | E2: based on
A3: light | B3: 4600000 | C3: 72000 | D3: 55 | E3: r19 Luna F (stopped early, 36 chunks)
A4: typical | B4: 40000000 | C4: 220000 | D4: 200 | E4: median of our 9 full 4-sitting paintings (rounds 17-19)
A5: heavy | B5: 75000000 | C5: 600000 | D5: 300 | E5: r19 Gemini B, r18 Space Bunny
A7: prompt split | B7: share
A8: cache read | B8: 0.89
A9: uncached input | B9: 0.08
A10: cache write | B10: 0.03
