Workbook

Sheet Notes
A1: Vision models on OpenRouter and what one painting would cost there (built 2026-09-28).
A2: Source: https://openrouter.ai/api/v1/models, fetched 2026-09-28: every model whose input modalities include image (list prices, $ per million tokens).
A3: Painting cost = prompt tokens x (uncached share x input price + cache-read share x cache-read price + cache-write share x cache-write price) + output tokens x output price + images x image price.
A4: No cache-read or cache-write price listed: those tokens are charged at the input price. 'typical $ no cache' charges the whole prompt at the input price (if caching doesn't work through a provider).
A5: Output includes reasoning tokens (they're billed as output). Thinking level changes output a lot: our runs were high to max.
A6: Token counts are from our session logs (Measured paintings); other models tokenize text and images differently, so treat every cost as a ballpark, x0.5 to x2.
A7: Painters need tool calls ('tool calls' = yes) and a long context (sessions reached 330K tokens before compaction; compaction works, tested 2026-09-28).
A8: Batch rows are half price but not interactive (not usable for painting). Router rows have variable prices.
A9: Rows shaded yellow are models we have painted with; 'used by us' says where. Subscriptions (ChatGPT for Luna, OpenCode Go/Zen) were cheaper than these list prices.

Sheet Profiles
A1: Token profile of one painting in 4 sittings (edit the blue cells; every cost recalculates)
A3: profile | B3: prompt tokens (all) | C3: output tokens | D3: images | E3: based on
A4: light | B4: 4600000 | C4: 72000 | D4: 55 | E4: r19 Luna F (GPT-6 Luna, stopped early: 36 chunks)
A5: typical | B5: 40000000 | C5: 220000 | D5: 200 | E5: median of the 9 full 4-sitting paintings (rounds 17-19)
A6: heavy | B6: 75000000 | C6: 600000 | D6: 300 | E6: r19 Gemini B (57M, 654K), r18 Space Bunny (90M, 585K)
A8: prompt split | B8: share
A9: cache read | B9: 0.89
A10: uncached input | B10: 0.08
A11: cache write | B11: 0.03
A12: (measured: Opus 97% read + 3-10% writes; Gemini 92%; DeepSeek 85%; Muse 95%)

Sheet Models
A1: model id | B1: name | C1: used by us | D1: tool calls | E1: text out | F1: context | G1: kind | H1: $/M input | I1: $/M output | J1: $/M cache read | K1: $/M cache write | L1: $/image | M1: light $ | N1: typical $ | O1: heavy $ | P1: typical $ no cache | Q1: created | R1: expires
A2: stealth/space-bunny-alpha | B2: Space Bunny Alpha | C2: r18 as space-bunny-free (via Go) | D2: yes | E2: yes | F2: 1000000 | G2: free | H2: 0 | I2: 0 | M2: =IF(OR(H2="",I2=""),"",(Profiles!$B$4*(Profiles!$B$10*H2+Profiles!$B$9*IF(J2="",H2,J2)+Profiles!$B$11*IF(K2="",H2,K2))+Profiles!$C$4*I2)/1000000+Profiles!$D$4*IF(L2="",0,L2)) | N2: =IF(OR(H2="",I2=""),"",(Profiles!$B$5*(Profiles!$B$10*H2+Profiles!$B$9*IF(J2="",H2,J2)+Profiles!$B$11*IF(K2="",H2,K2))+Profiles!$C$5*I2)/1000000+Profiles!$D$5*IF(L2="",0,L2)) | O2: =IF(OR(H2="",I2=""),"",(Profiles!$B$6*(Profiles!$B$10*H2+Profiles!$B$9*IF(J2="",H2,J2)+Profiles!$B$11*IF(K2="",H2,K2))+Profiles!$C$6*I2)/1000000+Profiles!$D$6*IF(L2="",0,L2)) | P2: =IF(OR(H2="",I2=""),"",(Profiles!$B$5*(Profiles!$B$10*H2+Profiles!$B$9*H2+Profiles!$B$11*H2)+Profiles!$C$5*I2)/1000000+Profiles!$D$5*IF(L2="",0,L2)) | Q2: 2026-09-23
A3: qwen/qwen3.8-27b:free | B3: Qwen: Qwen3.8 27B (free) | D3: yes | E3: yes | F3: 262144 | G3: free | H3: 0 | I3: 0 | M3: =IF(OR(H3="",I3=""),"",(Profiles!$B$4*(Profiles!$B$10*H3+Profiles!$B$9*IF(J3="",H3,J3)+Profiles!$B$11*IF(K3="",H3,K3))+Profiles!$C$4*I3)/1000000+Profiles!$D$4*IF(L3="",0,L3)) | N3: =IF(OR(H3="",I3=""),"",(Profiles!$B$5*(Profiles!$B$10*H3+Profiles!$B$9*IF(J3="",H3,J3)+Profiles!$B$11*IF(K3="",H3,K3))+Profiles!$C$5*I3)/1000000+Profiles!$D$5*IF(L3="",0,L3)) | O3: =IF(OR(H3="",I3=""),"",(Profiles!$B$6*(Profiles!$B$10*H3+Profiles!$B$9*IF(J3="",H3,J3)+Profiles!$B$11*IF(K3="",H3,K3))+Profiles!$C$6*I3)/1000000+Profiles!$D$6*IF(L3="",0,L3)) | P3: =IF(OR(H3="",I3=""),"",(Profiles!$B$5*(Profiles!$B$10*H3+Profiles!$B$9*H3+Profiles!$B$11*H3)+Profiles!$C$5*I3)/1000000+Profiles!$D$5*IF(L3="",0,L3)) | Q3: 2026-08-14
A4: dots-studio/dots-3-note-preview:free | B4: Dots Studio: Dots3-Note Preview (free) | D4: yes | E4: yes | F4: 512000 | G4: free | H4: 0 | I4: 0 | M4: =IF(OR(H4="",I4=""),"",(Profiles!$B$4*(Profiles!$B$10*H4+Profiles!$B$9*IF(J4="",H4,J4)+Profiles!$B$11*IF(K4="",H4,K4))+Profiles!$C$4*I4)/1000000+Profiles!$D$4*IF(L4="",0,L4)) | N4: =IF(OR(H4="",I4=""),"",(Profiles!$B$5*(Profiles!$B$10*H4+Profiles!$B$9*IF(J4="",H4,J4)+Profiles!$B$11*IF(K4="",H4,K4))+Profiles!$C$5*I4)/1000000+Profiles!$D$5*IF(L4="",0,L4)) | O4: =IF(OR(H4="",I4=""),"",(Profiles!$B$6*(Profiles!$B$10*H4+Profiles!$B$9*IF(J4="",H4,J4)+Profiles!$B$11*IF(K4="",H4,K4))+Profiles!$C$6*I4)/1000000+Profiles!$D$6*IF(L4="",0,L4)) | P4: =IF(OR(H4="",I4=""),"",(Profiles!$B$5*(Profiles!$B$10*H4+Profiles!$B$9*H4+Profiles!$B$11*H4)+Profiles!$C$5*I4)/1000000+Profiles!$D$5*IF(L4="",0,L4)) | Q4: 2026-08-14
A5: thinkingmachines/inkling-small:free | B5: Thinking Machines: Inkling Small (free) | D5: yes | E5: yes | F5: 1048576 | G5: free | H5: 0 | I5: 0 | M5: =IF(OR(H5="",I5=""),"",(Profiles!$B$4*(Profiles!$B$10*H5+Profiles!$B$9*IF(J5="",H5,J5)+Profiles!$B$11*IF(K5="",H5,K5))+Profiles!$C$4*I5)/1000000+Profiles!$D$4*IF(L5="",0,L5)) | N5: =IF(OR(H5="",I5=""),"",(Profiles!$B$5*(Profiles!$B$10*H5+Profiles!$B$9*IF(J5="",H5,J5)+Profiles!$B$11*IF(K5="",H5,K5))+Profiles!$C$5*I5)/1000000+Profiles!$D$5*IF(L5="",0,L5)) | O5: =IF(OR(H5="",I5=""),"",(Profiles!$B$6*(Profiles!$B$10*H5+Profiles!$B$9*IF(J5="",H5,J5)+Profiles!$B$11*IF(K5="",H5,K5))+Profiles!$C$6*I5)/1000000+Profiles!$D$6*IF(L5="",0,L5)) | P5: =IF(OR(H5="",I5=""),"",(Profiles!$B$5*(Profiles!$B$10*H5+Profiles!$B$9*H5+Profiles!$B$11*H5)+Profiles!$C$5*I5)/1000000+Profiles!$D$5*IF(L5="",0,L5)) | Q5: 2026-07-30
A6: thinkingmachines/inkling:free | B6: Thinking Machines: Inkling (free) | D6: yes | E6: yes | F6: 1048576 | G6: free | H6: 0 | I6: 0 | M6: =IF(OR(H6="",I6=""),"",(Profiles!$B$4*(Profiles!$B$10*H6+Profiles!$B$9*IF(J6="",H6,J6)+Profiles!$B$11*IF(K6="",H6,K6))+Profiles!$C$4*I6)/1000000+Profiles!$D$4*IF(L6="",0,L6)) | N6: =IF(OR(H6="",I6=""),"",(Profiles!$B$5*(Profiles!$B$10*H6+Profiles!$B$9*IF(J6="",H6,J6)+Profiles!$B$11*IF(K6="",H6,K6))+Profiles!$C$5*I6)/1000000+Profiles!$D$5*IF(L6="",0,L6)) | O6: =IF(OR(H6="",I6=""),"",(Profiles!$B$6*(Profiles!$B$10*H6+Profiles!$B$9*IF(J6="",H6,J6)+Profiles!$B$11*IF(K6="",H6,K6))+Profiles!$C$6*I6)/1000000+Profiles!$D$6*IF(L6="",0,L6)) | P6: =IF(OR(H6="",I6=""),"",(Profiles!$B$5*(Profiles!$B$10*H6+Profiles!$B$9*H6+Profiles!$B$11*H6)+Profiles!$C$5*I6)/1000000+Profiles!$D$5*IF(L6="",0,L6)) | Q6: 2026-07-17
A7: nvidia/nemotron-3-nano-omni-30b-a3b-reasoning:free | B7: NVIDIA: Nemotron 3 Nano Omni (free) | D7: yes | E7: yes | F7: 256000 | G7: free | H7: 0 | I7: 0 | M7: =IF(OR(H7="",I7=""),"",(Profiles!$B$4*(Profiles!$B$10*H7+Profiles!$B$9*IF(J7="",H7,J7)+Profiles!$B$11*IF(K7="",H7,K7))+Profiles!$C$4*I7)/1000000+Profiles!$D$4*IF(L7="",0,L7)) | N7: =IF(OR(H7="",I7=""),"",(Profiles!$B$5*(Profiles!$B$10*H7+Profiles!$B$9*IF(J7="",H7,J7)+Profiles!$B$11*IF(K7="",H7,K7))+Profiles!$C$5*I7)/1000000+Profiles!$D$5*IF(L7="",0,L7)) | O7: =IF(OR(H7="",I7=""),"",(Profiles!$B$6*(Profiles!$B$10*H7+Profiles!$B$9*IF(J7="",H7,J7)+Profiles!$B$11*IF(K7="",H7,K7))+Profiles!$C$6*I7)/1000000+Profiles!$D$6*IF(L7="",0,L7)) | P7: =IF(OR(H7="",I7=""),"",(Profiles!$B$5*(Profiles!$B$10*H7+Profiles!$B$9*H7+Profiles!$B$11*H7)+Profiles!$C$5*I7)/1000000+Profiles!$D$5*IF(L7="",0,L7)) | Q7: 2026-04-28
A8: google/gemma-4-26b-a4b-it:free | B8: Google: Gemma 4 26B A4B (free) | D8: yes | E8: yes | F8: 262144 | G8: free | H8: 0 | I8: 0 | M8: =IF(OR(H8="",I8=""),"",(Profiles!$B$4*(Profiles!$B$10*H8+Profiles!$B$9*IF(J8="",H8,J8)+Profiles!$B$11*IF(K8="",H8,K8))+Profiles!$C$4*I8)/1000000+Profiles!$D$4*IF(L8="",0,L8)) | N8: =IF(OR(H8="",I8=""),"",(Profiles!$B$5*(Profiles!$B$10*H8+Profiles!$B$9*IF(J8="",H8,J8)+Profiles!$B$11*IF(K8="",H8,K8))+Profiles!$C$5*I8)/1000000+Profiles!$D$5*IF(L8="",0,L8)) | O8: =IF(OR(H8="",I8=""),"",(Profiles!$B$6*(Profiles!$B$10*H8+Profiles!$B$9*IF(J8="",H8,J8)+Profiles!$B$11*IF(K8="",H8,K8))+Profiles!$C$6*I8)/1000000+Profiles!$D$6*IF(L8="",0,L8)) | P8: =IF(OR(H8="",I8=""),"",(Profiles!$B$5*(Profiles!$B$10*H8+Profiles!$B$9*H8+Profiles!$B$11*H8)+Profiles!$C$5*I8)/1000000+Profiles!$D$5*IF(L8="",0,L8)) | Q8: 2026-04-03
A9: google/gemma-4-31b-it:free | B9: Google: Gemma 4 31B (free) | D9: yes | E9: yes | F9: 262144 | G9: free | H9: 0 | I9: 0 | M9: =IF(OR(H9="",I9=""),"",(Profiles!$B$4*(Profiles!$B$10*H9+Profiles!$B$9*IF(J9="",H9,J9)+Profiles!$B$11*IF(K9="",H9,K9))+Profiles!$C$4*I9)/1000000+Profiles!$D$4*IF(L9="",0,L9)) | N9: =IF(OR(H9="",I9=""),"",(Profiles!$B$5*(Profiles!$B$10*H9+Profiles!$B$9*IF(J9="",H9,J9)+Profiles!$B$11*IF(K9="",H9,K9))+Profiles!$C$5*I9)/1000000+Profiles!$D$5*IF(L9="",0,L9)) | O9: =IF(OR(H9="",I9=""),"",(Profiles!$B$6*(Profiles!$B$10*H9+Profiles!$B$9*IF(J9="",H9,J9)+Profiles!$B$11*IF(K9="",H9,K9))+Profiles!$C$6*I9)/1000000+Profiles!$D$6*IF(L9="",0,L9)) | P9: =IF(OR(H9="",I9=""),"",(Profiles!$B$5*(Profiles!$B$10*H9+Profiles!$B$9*H9+Profiles!$B$11*H9)+Profiles!$C$5*I9)/1000000+Profiles!$D$5*IF(L9="",0,L9)) | Q9: 2026-04-02
A10: openrouter/free | B10: Free Models Router | D10: yes | E10: yes | F10: 200000 | G10: free | H10: 0 | I10: 0 | M10: =IF(OR(H10="",I10=""),"",(Profiles!$B$4*(Profiles!$B$10*H10+Profiles!$B$9*IF(J10="",H10,J10)+Profiles!$B$11*IF(K10="",H10,K10))+Profiles!$C$4*I10)/1000000+Profiles!$D$4*IF(L10="",0,L10)) | N10: =IF(OR(H10="",I10=""),"",(Profiles!$B$5*(Profiles!$B$10*H10+Profiles!$B$9*IF(J10="",H10,J10)+Profiles!$B$11*IF(K10="",H10,K10))+Profiles!$C$5*I10)/1000000+Profiles!$D$5*IF(L10="",0,L10)) | O10: =IF(OR(H10="",I10=""),"",(Profiles!$B$6*(Profiles!$B$10*H10+Profiles!$B$9*IF(J10="",H10,J10)+Profiles!$B$11*IF(K10="",H10,K10))+Profiles!$C$6*I10)/1000000+Profiles!$D$6*IF(L10="",0,L10)) | P10: =IF(OR(H10="",I10=""),"",(Profiles!$B$5*(Profiles!$B$10*H10+Profiles!$B$9*H10+Profiles!$B$11*H10)+Profiles!$C$5*I10)/1000000+Profiles!$D$5*IF(L10="",0,L10)) | Q10: 2026-02-01
A11: ~deepseek/deepseek-flash-latest | B11: DeepSeek: DeepSeek Flash Latest | D11: yes | E11: yes | F11: 1048576 | G11: alias (latest) | H11: 0.035 | I11: 0.29 | J11: 0.001 | M11: =IF(OR(H11="",I11=""),"",(Profiles!$B$4*(Profiles!$B$10*H11+Profiles!$B$9*IF(J11="",H11,J11)+Profiles!$B$11*IF(K11="",H11,K11))+Profiles!$C$4*I11)/1000000+Profiles!$D$4*IF(L11="",0,L11)) | N11: =IF(OR(H11="",I11=""),"",(Profiles!$B$5*(Profiles!$B$10*H11+Profiles!$B$9*IF(J11="",H11,J11)+Profiles!$B$11*IF(K11="",H11,K11))+Profiles!$C$5*I11)/1000000+Profiles!$D$5*IF(L11="",0,L11)) | O11: =IF(OR(H11="",I11=""),"",(Profiles!$B$6*(Profiles!$B$10*H11+Profiles!$B$9*IF(J11="",H11,J11)+Profiles!$B$11*IF(K11="",H11,K11))+Profiles!$C$6*I11)/1000000+Profiles!$D$6*IF(L11="",0,L11)) | P11: =IF(OR(H11="",I11=""),"",(Profiles!$B$5*(Profiles!$B$10*H11+Profiles!$B$9*H11+Profiles!$B$11*H11)+Profiles!$C$5*I11)/1000000+Profiles!$D$5*IF(L11="",0,L11)) | Q11: 2026-09-14
A12: deepseek/deepseek-v4.1-flash | B12: DeepSeek: DeepSeek V4.1 Flash | C12: r18 (via Go) | D12: yes | E12: yes | F12: 1048576 | H12: 0.035 | I12: 0.29 | J12: 0.001 | M12: =IF(OR(H12="",I12=""),"",(Profiles!$B$4*(Profiles!$B$10*H12+Profiles!$B$9*IF(J12="",H12,J12)+Profiles!$B$11*IF(K12="",H12,K12))+Profiles!$C$4*I12)/1000000+Profiles!$D$4*IF(L12="",0,L12)) | N12: =IF(OR(H12="",I12=""),"",(Profiles!$B$5*(Profiles!$B$10*H12+Profiles!$B$9*IF(J12="",H12,J12)+Profiles!$B$11*IF(K12="",H12,K12))+Profiles!$C$5*I12)/1000000+Profiles!$D$5*IF(L12="",0,L12)) | O12: =IF(OR(H12="",I12=""),"",(Profiles!$B$6*(Profiles!$B$10*H12+Profiles!$B$9*IF(J12="",H12,J12)+Profiles!$B$11*IF(K12="",H12,K12))+Profiles!$C$6*I12)/1000000+Profiles!$D$6*IF(L12="",0,L12)) | P12: =IF(OR(H12="",I12=""),"",(Profiles!$B$5*(Profiles!$B$10*H12+Profiles!$B$9*H12+Profiles!$B$11*H12)+Profiles!$C$5*I12)/1000000+Profiles!$D$5*IF(L12="",0,L12)) | Q12: 2026-09-10
A13: inclusionai/ling-3.0-flash-vl | B13: inclusionAI: Ling 3.0 Flash VL | D13: yes | E13: yes | F13: 262144 | H13: 0.021 | I13: 0.0616 | J13: 0.0042 | M13: =IF(OR(H13="",I13=""),"",(Profiles!$B$4*(Profiles!$B$10*H13+Profiles!$B$9*IF(J13="",H13,J13)+Profiles!$B$11*IF(K13="",H13,K13))+Profiles!$C$4*I13)/1000000+Profiles!$D$4*IF(L13="",0,L13)) | N13: =IF(OR(H13="",I13=""),"",(Profiles!$B$5*(Profiles!$B$10*H13+Profiles!$B$9*IF(J13="",H13,J13)+Profiles!$B$11*IF(K13="",H13,K13))+Profiles!$C$5*I13)/1000000+Profiles!$D$5*IF(L13="",0,L13)) | O13: =IF(OR(H13="",I13=""),"",(Profiles!$B$6*(Profiles!$B$10*H13+Profiles!$B$9*IF(J13="",H13,J13)+Profiles!$B$11*IF(K13="",H13,K13))+Profiles!$C$6*I13)/1000000+Profiles!$D$6*IF(L13="",0,L13)) | P13: =IF(OR(H13="",I13=""),"",(Profiles!$B$5*(Profiles!$B$10*H13+Profiles!$B$9*H13+Profiles!$B$11*H13)+Profiles!$C$5*I13)/1000000+Profiles!$D$5*IF(L13="",0,L13)) | Q13: 2026-09-10
A14: qwen/qwen3.7-flash | B14: Qwen: Qwen3.7 Flash | D14: yes | E14: yes | F14: 1000000 | H14: 0.03 | I14: 0.13 | J14: 0.006 | K14: 0.038 | M14: =IF(OR(H14="",I14=""),"",(Profiles!$B$4*(Profiles!$B$10*H14+Profiles!$B$9*IF(J14="",H14,J14)+Profiles!$B$11*IF(K14="",H14,K14))+Profiles!$C$4*I14)/1000000+Profiles!$D$4*IF(L14="",0,L14)) | N14: =IF(OR(H14="",I14=""),"",(Profiles!$B$5*(Profiles!$B$10*H14+Profiles!$B$9*IF(J14="",H14,J14)+Profiles!$B$11*IF(K14="",H14,K14))+Profiles!$C$5*I14)/1000000+Profiles!$D$5*IF(L14="",0,L14)) | O14: =IF(OR(H14="",I14=""),"",(Profiles!$B$6*(Profiles!$B$10*H14+Profiles!$B$9*IF(J14="",H14,J14)+Profiles!$B$11*IF(K14="",H14,K14))+Profiles!$C$6*I14)/1000000+Profiles!$D$6*IF(L14="",0,L14)) | P14: =IF(OR(H14="",I14=""),"",(Profiles!$B$5*(Profiles!$B$10*H14+Profiles!$B$9*H14+Profiles!$B$11*H14)+Profiles!$C$5*I14)/1000000+Profiles!$D$5*IF(L14="",0,L14)) | Q14: 2026-07-27
A15: openai/gpt-5-nano | B15: OpenAI: GPT-5 Nano | D15: yes | E15: yes | F15: 400000 | H15: 0.05 | I15: 0.4 | J15: 0.005 | M15: =IF(OR(H15="",I15=""),"",(Profiles!$B$4*(Profiles!$B$10*H15+Profiles!$B$9*IF(J15="",H15,J15)+Profiles!$B$11*IF(K15="",H15,K15))+Profiles!$C$4*I15)/1000000+Profiles!$D$4*IF(L15="",0,L15)) | N15: =IF(OR(H15="",I15=""),"",(Profiles!$B$5*(Profiles!$B$10*H15+Profiles!$B$9*IF(J15="",H15,J15)+Profiles!$B$11*IF(K15="",H15,K15))+Profiles!$C$5*I15)/1000000+Profiles!$D$5*IF(L15="",0,L15)) | O15: =IF(OR(H15="",I15=""),"",(Profiles!$B$6*(Profiles!$B$10*H15+Profiles!$B$9*IF(J15="",H15,J15)+Profiles!$B$11*IF(K15="",H15,K15))+Profiles!$C$6*I15)/1000000+Profiles!$D$6*IF(L15="",0,L15)) | P15: =IF(OR(H15="",I15=""),"",(Profiles!$B$5*(Profiles!$B$10*H15+Profiles!$B$9*H15+Profiles!$B$11*H15)+Profiles!$C$5*I15)/1000000+Profiles!$D$5*IF(L15="",0,L15)) | Q15: 2025-08-07
A16: meta/muse-spark-1.3-contributor | B16: Meta: Muse Spark 1.3 Contributor | D16: yes | E16: yes | F16: 1048576 | H16: 0.1 | I16: 0.2 | J16: 0.002 | M16: =IF(OR(H16="",I16=""),"",(Profiles!$B$4*(Profiles!$B$10*H16+Profiles!$B$9*IF(J16="",H16,J16)+Profiles!$B$11*IF(K16="",H16,K16))+Profiles!$C$4*I16)/1000000+Profiles!$D$4*IF(L16="",0,L16)) | N16: =IF(OR(H16="",I16=""),"",(Profiles!$B$5*(Profiles!$B$10*H16+Profiles!$B$9*IF(J16="",H16,J16)+Profiles!$B$11*IF(K16="",H16,K16))+Profiles!$C$5*I16)/1000000+Profiles!$D$5*IF(L16="",0,L16)) | O16: =IF(OR(H16="",I16=""),"",(Profiles!$B$6*(Profiles!$B$10*H16+Profiles!$B$9*IF(J16="",H16,J16)+Profiles!$B$11*IF(K16="",H16,K16))+Profiles!$C$6*I16)/1000000+Profiles!$D$6*IF(L16="",0,L16)) | P16: =IF(OR(H16="",I16=""),"",(Profiles!$B$5*(Profiles!$B$10*H16+Profiles!$B$9*H16+Profiles!$B$11*H16)+Profiles!$C$5*I16)/1000000+Profiles!$D$5*IF(L16="",0,L16)) | Q16: 2026-09-02
A17: meta/muse-spark-1.2-contributor | B17: Meta: Muse Spark 1.2 Contributor | D17: yes | E17: yes | F17: 1048576 | H17: 0.1 | I17: 0.2 | J17: 0.002 | M17: =IF(OR(H17="",I17=""),"",(Profiles!$B$4*(Profiles!$B$10*H17+Profiles!$B$9*IF(J17="",H17,J17)+Profiles!$B$11*IF(K17="",H17,K17))+Profiles!$C$4*I17)/1000000+Profiles!$D$4*IF(L17="",0,L17)) | N17: =IF(OR(H17="",I17=""),"",(Profiles!$B$5*(Profiles!$B$10*H17+Profiles!$B$9*IF(J17="",H17,J17)+Profiles!$B$11*IF(K17="",H17,K17))+Profiles!$C$5*I17)/1000000+Profiles!$D$5*IF(L17="",0,L17)) | O17: =IF(OR(H17="",I17=""),"",(Profiles!$B$6*(Profiles!$B$10*H17+Profiles!$B$9*IF(J17="",H17,J17)+Profiles!$B$11*IF(K17="",H17,K17))+Profiles!$C$6*I17)/1000000+Profiles!$D$6*IF(L17="",0,L17)) | P17: =IF(OR(H17="",I17=""),"",(Profiles!$B$5*(Profiles!$B$10*H17+Profiles!$B$9*H17+Profiles!$B$11*H17)+Profiles!$C$5*I17)/1000000+Profiles!$D$5*IF(L17="",0,L17)) | Q17: 2026-08-21
A18: ~z-ai/glm-flash-latest | B18: Z.ai: GLM Flash Latest | D18: yes | E18: yes | F18: 1310720 | G18: alias (latest) | H18: 0.045 | I18: 0.14 | J18: 0.01 | M18: =IF(OR(H18="",I18=""),"",(Profiles!$B$4*(Profiles!$B$10*H18+Profiles!$B$9*IF(J18="",H18,J18)+Profiles!$B$11*IF(K18="",H18,K18))+Profiles!$C$4*I18)/1000000+Profiles!$D$4*IF(L18="",0,L18)) | N18: =IF(OR(H18="",I18=""),"",(Profiles!$B$5*(Profiles!$B$10*H18+Profiles!$B$9*IF(J18="",H18,J18)+Profiles!$B$11*IF(K18="",H18,K18))+Profiles!$C$5*I18)/1000000+Profiles!$D$5*IF(L18="",0,L18)) | O18: =IF(OR(H18="",I18=""),"",(Profiles!$B$6*(Profiles!$B$10*H18+Profiles!$B$9*IF(J18="",H18,J18)+Profiles!$B$11*IF(K18="",H18,K18))+Profiles!$C$6*I18)/1000000+Profiles!$D$6*IF(L18="",0,L18)) | P18: =IF(OR(H18="",I18=""),"",(Profiles!$B$5*(Profiles!$B$10*H18+Profiles!$B$9*H18+Profiles!$B$11*H18)+Profiles!$C$5*I18)/1000000+Profiles!$D$5*IF(L18="",0,L18)) | Q18: 2026-08-27
A19: xiaomi/mimo-v2.6-flash | B19: Xiaomi: MiMo-V2.6-Flash | D19: yes | E19: yes | F19: 1048576 | H19: 0.14 | I19: 0.28 | J19: 0.0028 | M19: =IF(OR(H19="",I19=""),"",(Profiles!$B$4*(Profiles!$B$10*H19+Profiles!$B$9*IF(J19="",H19,J19)+Profiles!$B$11*IF(K19="",H19,K19))+Profiles!$C$4*I19)/1000000+Profiles!$D$4*IF(L19="",0,L19)) | N19: =IF(OR(H19="",I19=""),"",(Profiles!$B$5*(Profiles!$B$10*H19+Profiles!$B$9*IF(J19="",H19,J19)+Profiles!$B$11*IF(K19="",H19,K19))+Profiles!$C$5*I19)/1000000+Profiles!$D$5*IF(L19="",0,L19)) | O19: =IF(OR(H19="",I19=""),"",(Profiles!$B$6*(Profiles!$B$10*H19+Profiles!$B$9*IF(J19="",H19,J19)+Profiles!$B$11*IF(K19="",H19,K19))+Profiles!$C$6*I19)/1000000+Profiles!$D$6*IF(L19="",0,L19)) | P19: =IF(OR(H19="",I19=""),"",(Profiles!$B$5*(Profiles!$B$10*H19+Profiles!$B$9*H19+Profiles!$B$11*H19)+Profiles!$C$5*I19)/1000000+Profiles!$D$5*IF(L19="",0,L19)) | Q19: 2026-09-21
A20: xiaomi/mimo-v2.5 | B20: Xiaomi: MiMo-V2.5 | D20: yes | E20: yes | F20: 1050000 | H20: 0.14 | I20: 0.28 | J20: 0.0028 | M20: =IF(OR(H20="",I20=""),"",(Profiles!$B$4*(Profiles!$B$10*H20+Profiles!$B$9*IF(J20="",H20,J20)+Profiles!$B$11*IF(K20="",H20,K20))+Profiles!$C$4*I20)/1000000+Profiles!$D$4*IF(L20="",0,L20)) | N20: =IF(OR(H20="",I20=""),"",(Profiles!$B$5*(Profiles!$B$10*H20+Profiles!$B$9*IF(J20="",H20,J20)+Profiles!$B$11*IF(K20="",H20,K20))+Profiles!$C$5*I20)/1000000+Profiles!$D$5*IF(L20="",0,L20)) | O20: =IF(OR(H20="",I20=""),"",(Profiles!$B$6*(Profiles!$B$10*H20+Profiles!$B$9*IF(J20="",H20,J20)+Profiles!$B$11*IF(K20="",H20,K20))+Profiles!$C$6*I20)/1000000+Profiles!$D$6*IF(L20="",0,L20)) | P20: =IF(OR(H20="",I20=""),"",(Profiles!$B$5*(Profiles!$B$10*H20+Profiles!$B$9*H20+Profiles!$B$11*H20)+Profiles!$C$5*I20)/1000000+Profiles!$D$5*IF(L20="",0,L20)) | Q20: 2026-04-22
A21: mistralai/ministral-3b-2512 | B21: Mistral: Ministral 3 3B 2512 | D21: yes | E21: yes | F21: 131072 | H21: 0.1 | I21: 0.1 | J21: 0.01 | M21: =IF(OR(H21="",I21=""),"",(Profiles!$B$4*(Profiles!$B$10*H21+Profiles!$B$9*IF(J21="",H21,J21)+Profiles!$B$11*IF(K21="",H21,K21))+Profiles!$C$4*I21)/1000000+Profiles!$D$4*IF(L21="",0,L21)) | N21: =IF(OR(H21="",I21=""),"",(Profiles!$B$5*(Profiles!$B$10*H21+Profiles!$B$9*IF(J21="",H21,J21)+Profiles!$B$11*IF(K21="",H21,K21))+Profiles!$C$5*I21)/1000000+Profiles!$D$5*IF(L21="",0,L21)) | O21: =IF(OR(H21="",I21=""),"",(Profiles!$B$6*(Profiles!$B$10*H21+Profiles!$B$9*IF(J21="",H21,J21)+Profiles!$B$11*IF(K21="",H21,K21))+Profiles!$C$6*I21)/1000000+Profiles!$D$6*IF(L21="",0,L21)) | P21: =IF(OR(H21="",I21=""),"",(Profiles!$B$5*(Profiles!$B$10*H21+Profiles!$B$9*H21+Profiles!$B$11*H21)+Profiles!$C$5*I21)/1000000+Profiles!$D$5*IF(L21="",0,L21)) | Q21: 2025-12-02
A22: google/gemini-2.5-flash-lite | B22: Google: Gemini 2.5 Flash Lite | D22: yes | E22: yes | F22: 1048576 | H22: 0.1 | I22: 0.4 | J22: 0.01 | K22: 0.083333333 | L22: 1e-07 | M22: =IF(OR(H22="",I22=""),"",(Profiles!$B$4*(Profiles!$B$10*H22+Profiles!$B$9*IF(J22="",H22,J22)+Profiles!$B$11*IF(K22="",H22,K22))+Profiles!$C$4*I22)/1000000+Profiles!$D$4*IF(L22="",0,L22)) | N22: =IF(OR(H22="",I22=""),"",(Profiles!$B$5*(Profiles!$B$10*H22+Profiles!$B$9*IF(J22="",H22,J22)+Profiles!$B$11*IF(K22="",H22,K22))+Profiles!$C$5*I22)/1000000+Profiles!$D$5*IF(L22="",0,L22)) | O22: =IF(OR(H22="",I22=""),"",(Profiles!$B$6*(Profiles!$B$10*H22+Profiles!$B$9*IF(J22="",H22,J22)+Profiles!$B$11*IF(K22="",H22,K22))+Profiles!$C$6*I22)/1000000+Profiles!$D$6*IF(L22="",0,L22)) | P22: =IF(OR(H22="",I22=""),"",(Profiles!$B$5*(Profiles!$B$10*H22+Profiles!$B$9*H22+Profiles!$B$11*H22)+Profiles!$C$5*I22)/1000000+Profiles!$D$5*IF(L22="",0,L22)) | Q22: 2025-07-22 | R22: 2026-10-20
A23: openai/gpt-6-luna-pro | B23: OpenAI: GPT-6 Luna Pro | D23: yes | E23: yes | F23: 1050000 | H23: 0.1 | I23: 0.5 | J23: 0.01 | K23: 0.125 | M23: =IF(OR(H23="",I23=""),"",(Profiles!$B$4*(Profiles!$B$10*H23+Profiles!$B$9*IF(J23="",H23,J23)+Profiles!$B$11*IF(K23="",H23,K23))+Profiles!$C$4*I23)/1000000+Profiles!$D$4*IF(L23="",0,L23)) | N23: =IF(OR(H23="",I23=""),"",(Profiles!$B$5*(Profiles!$B$10*H23+Profiles!$B$9*IF(J23="",H23,J23)+Profiles!$B$11*IF(K23="",H23,K23))+Profiles!$C$5*I23)/1000000+Profiles!$D$5*IF(L23="",0,L23)) | O23: =IF(OR(H23="",I23=""),"",(Profiles!$B$6*(Profiles!$B$10*H23+Profiles!$B$9*IF(J23="",H23,J23)+Profiles!$B$11*IF(K23="",H23,K23))+Profiles!$C$6*I23)/1000000+Profiles!$D$6*IF(L23="",0,L23)) | P23: =IF(OR(H23="",I23=""),"",(Profiles!$B$5*(Profiles!$B$10*H23+Profiles!$B$9*H23+Profiles!$B$11*H23)+Profiles!$C$5*I23)/1000000+Profiles!$D$5*IF(L23="",0,L23)) | Q23: 2026-09-22
A24: openai/gpt-6-luna | B24: OpenAI: GPT-6 Luna | C24: r19 (via ChatGPT subscription) | D24: yes | E24: yes | F24: 1050000 | H24: 0.1 | I24: 0.5 | J24: 0.01 | K24: 0.125 | M24: =IF(OR(H24="",I24=""),"",(Profiles!$B$4*(Profiles!$B$10*H24+Profiles!$B$9*IF(J24="",H24,J24)+Profiles!$B$11*IF(K24="",H24,K24))+Profiles!$C$4*I24)/1000000+Profiles!$D$4*IF(L24="",0,L24)) | N24: =IF(OR(H24="",I24=""),"",(Profiles!$B$5*(Profiles!$B$10*H24+Profiles!$B$9*IF(J24="",H24,J24)+Profiles!$B$11*IF(K24="",H24,K24))+Profiles!$C$5*I24)/1000000+Profiles!$D$5*IF(L24="",0,L24)) | O24: =IF(OR(H24="",I24=""),"",(Profiles!$B$6*(Profiles!$B$10*H24+Profiles!$B$9*IF(J24="",H24,J24)+Profiles!$B$11*IF(K24="",H24,K24))+Profiles!$C$6*I24)/1000000+Profiles!$D$6*IF(L24="",0,L24)) | P24: =IF(OR(H24="",I24=""),"",(Profiles!$B$5*(Profiles!$B$10*H24+Profiles!$B$9*H24+Profiles!$B$11*H24)+Profiles!$C$5*I24)/1000000+Profiles!$D$5*IF(L24="",0,L24)) | Q24: 2026-09-22
A25: ~openai/gpt-luna-latest | B25: OpenAI: GPT Luna Latest | D25: yes | E25: yes | F25: 1050000 | G25: alias (latest) | H25: 0.1 | I25: 0.5 | J25: 0.01 | K25: 0.125 | M25: =IF(OR(H25="",I25=""),"",(Profiles!$B$4*(Profiles!$B$10*H25+Profiles!$B$9*IF(J25="",H25,J25)+Profiles!$B$11*IF(K25="",H25,K25))+Profiles!$C$4*I25)/1000000+Profiles!$D$4*IF(L25="",0,L25)) | N25: =IF(OR(H25="",I25=""),"",(Profiles!$B$5*(Profiles!$B$10*H25+Profiles!$B$9*IF(J25="",H25,J25)+Profiles!$B$11*IF(K25="",H25,K25))+Profiles!$C$5*I25)/1000000+Profiles!$D$5*IF(L25="",0,L25)) | O25: =IF(OR(H25="",I25=""),"",(Profiles!$B$6*(Profiles!$B$10*H25+Profiles!$B$9*IF(J25="",H25,J25)+Profiles!$B$11*IF(K25="",H25,K25))+Profiles!$C$6*I25)/1000000+Profiles!$D$6*IF(L25="",0,L25)) | P25: =IF(OR(H25="",I25=""),"",(Profiles!$B$5*(Profiles!$B$10*H25+Profiles!$B$9*H25+Profiles!$B$11*H25)+Profiles!$C$5*I25)/1000000+Profiles!$D$5*IF(L25="",0,L25)) | Q25: 2026-09-11
A26: mistralai/ministral-8b-2512 | B26: Mistral: Ministral 3 8B 2512 | D26: yes | E26: yes | F26: 262144 | H26: 0.15 | I26: 0.15 | J26: 0.015 | M26: =IF(OR(H26="",I26=""),"",(Profiles!$B$4*(Profiles!$B$10*H26+Profiles!$B$9*IF(J26="",H26,J26)+Profiles!$B$11*IF(K26="",H26,K26))+Profiles!$C$4*I26)/1000000+Profiles!$D$4*IF(L26="",0,L26)) | N26: =IF(OR(H26="",I26=""),"",(Profiles!$B$5*(Profiles!$B$10*H26+Profiles!$B$9*IF(J26="",H26,J26)+Profiles!$B$11*IF(K26="",H26,K26))+Profiles!$C$5*I26)/1000000+Profiles!$D$5*IF(L26="",0,L26)) | O26: =IF(OR(H26="",I26=""),"",(Profiles!$B$6*(Profiles!$B$10*H26+Profiles!$B$9*IF(J26="",H26,J26)+Profiles!$B$11*IF(K26="",H26,K26))+Profiles!$C$6*I26)/1000000+Profiles!$D$6*IF(L26="",0,L26)) | P26: =IF(OR(H26="",I26=""),"",(Profiles!$B$5*(Profiles!$B$10*H26+Profiles!$B$9*H26+Profiles!$B$11*H26)+Profiles!$C$5*I26)/1000000+Profiles!$D$5*IF(L26="",0,L26)) | Q26: 2025-12-02
A27: mistralai/mistral-small-2603 | B27: Mistral: Mistral Small 4 | D27: yes | E27: yes | F27: 262144 | H27: 0.15 | I27: 0.6 | J27: 0.015 | M27: =IF(OR(H27="",I27=""),"",(Profiles!$B$4*(Profiles!$B$10*H27+Profiles!$B$9*IF(J27="",H27,J27)+Profiles!$B$11*IF(K27="",H27,K27))+Profiles!$C$4*I27)/1000000+Profiles!$D$4*IF(L27="",0,L27)) | N27: =IF(OR(H27="",I27=""),"",(Profiles!$B$5*(Profiles!$B$10*H27+Profiles!$B$9*IF(J27="",H27,J27)+Profiles!$B$11*IF(K27="",H27,K27))+Profiles!$C$5*I27)/1000000+Profiles!$D$5*IF(L27="",0,L27)) | O27: =IF(OR(H27="",I27=""),"",(Profiles!$B$6*(Profiles!$B$10*H27+Profiles!$B$9*IF(J27="",H27,J27)+Profiles!$B$11*IF(K27="",H27,K27))+Profiles!$C$6*I27)/1000000+Profiles!$D$6*IF(L27="",0,L27)) | P27: =IF(OR(H27="",I27=""),"",(Profiles!$B$5*(Profiles!$B$10*H27+Profiles!$B$9*H27+Profiles!$B$11*H27)+Profiles!$C$5*I27)/1000000+Profiles!$D$5*IF(L27="",0,L27)) | Q27: 2026-03-16
A28: qwen/qwen3.8-omni-flash | B28: Qwen: Qwen3.8 Omni Flash | D28: yes | E28: yes | F28: 1000000 | H28: 0.15 | I28: 0.47 | J28: 0.016 | M28: =IF(OR(H28="",I28=""),"",(Profiles!$B$4*(Profiles!$B$10*H28+Profiles!$B$9*IF(J28="",H28,J28)+Profiles!$B$11*IF(K28="",H28,K28))+Profiles!$C$4*I28)/1000000+Profiles!$D$4*IF(L28="",0,L28)) | N28: =IF(OR(H28="",I28=""),"",(Profiles!$B$5*(Profiles!$B$10*H28+Profiles!$B$9*IF(J28="",H28,J28)+Profiles!$B$11*IF(K28="",H28,K28))+Profiles!$C$5*I28)/1000000+Profiles!$D$5*IF(L28="",0,L28)) | O28: =IF(OR(H28="",I28=""),"",(Profiles!$B$6*(Profiles!$B$10*H28+Profiles!$B$9*IF(J28="",H28,J28)+Profiles!$B$11*IF(K28="",H28,K28))+Profiles!$C$6*I28)/1000000+Profiles!$D$6*IF(L28="",0,L28)) | P28: =IF(OR(H28="",I28=""),"",(Profiles!$B$5*(Profiles!$B$10*H28+Profiles!$B$9*H28+Profiles!$B$11*H28)+Profiles!$C$5*I28)/1000000+Profiles!$D$5*IF(L28="",0,L28)) | Q28: 2026-09-21
A29: qwen/qwen3.8-flash | B29: Qwen: Qwen3.8 Flash | D29: yes | E29: yes | F29: 1000000 | H29: 0.15 | I29: 0.47 | J29: 0.016 | K29: 0.2 | M29: =IF(OR(H29="",I29=""),"",(Profiles!$B$4*(Profiles!$B$10*H29+Profiles!$B$9*IF(J29="",H29,J29)+Profiles!$B$11*IF(K29="",H29,K29))+Profiles!$C$4*I29)/1000000+Profiles!$D$4*IF(L29="",0,L29)) | N29: =IF(OR(H29="",I29=""),"",(Profiles!$B$5*(Profiles!$B$10*H29+Profiles!$B$9*IF(J29="",H29,J29)+Profiles!$B$11*IF(K29="",H29,K29))+Profiles!$C$5*I29)/1000000+Profiles!$D$5*IF(L29="",0,L29)) | O29: =IF(OR(H29="",I29=""),"",(Profiles!$B$6*(Profiles!$B$10*H29+Profiles!$B$9*IF(J29="",H29,J29)+Profiles!$B$11*IF(K29="",H29,K29))+Profiles!$C$6*I29)/1000000+Profiles!$D$6*IF(L29="",0,L29)) | P29: =IF(OR(H29="",I29=""),"",(Profiles!$B$5*(Profiles!$B$10*H29+Profiles!$B$9*H29+Profiles!$B$11*H29)+Profiles!$C$5*I29)/1000000+Profiles!$D$5*IF(L29="",0,L29)) | Q29: 2026-08-26
A30: openai/gpt-4.1-nano | B30: OpenAI: GPT-4.1 Nano | D30: yes | E30: yes | F30: 1047576 | H30: 0.1 | I30: 0.4 | J30: 0.025 | M30: =IF(OR(H30="",I30=""),"",(Profiles!$B$4*(Profiles!$B$10*H30+Profiles!$B$9*IF(J30="",H30,J30)+Profiles!$B$11*IF(K30="",H30,K30))+Profiles!$C$4*I30)/1000000+Profiles!$D$4*IF(L30="",0,L30)) | N30: =IF(OR(H30="",I30=""),"",(Profiles!$B$5*(Profiles!$B$10*H30+Profiles!$B$9*IF(J30="",H30,J30)+Profiles!$B$11*IF(K30="",H30,K30))+Profiles!$C$5*I30)/1000000+Profiles!$D$5*IF(L30="",0,L30)) | O30: =IF(OR(H30="",I30=""),"",(Profiles!$B$6*(Profiles!$B$10*H30+Profiles!$B$9*IF(J30="",H30,J30)+Profiles!$B$11*IF(K30="",H30,K30))+Profiles!$C$6*I30)/1000000+Profiles!$D$6*IF(L30="",0,L30)) | P30: =IF(OR(H30="",I30=""),"",(Profiles!$B$5*(Profiles!$B$10*H30+Profiles!$B$9*H30+Profiles!$B$11*H30)+Profiles!$C$5*I30)/1000000+Profiles!$D$5*IF(L30="",0,L30)) | Q30: 2025-04-14
A31: mistralai/ministral-14b-2512 | B31: Mistral: Ministral 3 14B 2512 | D31: yes | E31: yes | F31: 262144 | H31: 0.2 | I31: 0.2 | J31: 0.02 | M31: =IF(OR(H31="",I31=""),"",(Profiles!$B$4*(Profiles!$B$10*H31+Profiles!$B$9*IF(J31="",H31,J31)+Profiles!$B$11*IF(K31="",H31,K31))+Profiles!$C$4*I31)/1000000+Profiles!$D$4*IF(L31="",0,L31)) | N31: =IF(OR(H31="",I31=""),"",(Profiles!$B$5*(Profiles!$B$10*H31+Profiles!$B$9*IF(J31="",H31,J31)+Profiles!$B$11*IF(K31="",H31,K31))+Profiles!$C$5*I31)/1000000+Profiles!$D$5*IF(L31="",0,L31)) | O31: =IF(OR(H31="",I31=""),"",(Profiles!$B$6*(Profiles!$B$10*H31+Profiles!$B$9*IF(J31="",H31,J31)+Profiles!$B$11*IF(K31="",H31,K31))+Profiles!$C$6*I31)/1000000+Profiles!$D$6*IF(L31="",0,L31)) | P31: =IF(OR(H31="",I31=""),"",(Profiles!$B$5*(Profiles!$B$10*H31+Profiles!$B$9*H31+Profiles!$B$11*H31)+Profiles!$C$5*I31)/1000000+Profiles!$D$5*IF(L31="",0,L31)) | Q31: 2025-12-02
A32: z-ai/glm-5.3-flash | B32: Z.ai: GLM 5.3 Flash | C32: r18 (via Go) | D32: yes | E32: yes | F32: 1310720 | H32: 0.15 | I32: 0.5 | J32: 0.03 | M32: =IF(OR(H32="",I32=""),"",(Profiles!$B$4*(Profiles!$B$10*H32+Profiles!$B$9*IF(J32="",H32,J32)+Profiles!$B$11*IF(K32="",H32,K32))+Profiles!$C$4*I32)/1000000+Profiles!$D$4*IF(L32="",0,L32)) | N32: =IF(OR(H32="",I32=""),"",(Profiles!$B$5*(Profiles!$B$10*H32+Profiles!$B$9*IF(J32="",H32,J32)+Profiles!$B$11*IF(K32="",H32,K32))+Profiles!$C$5*I32)/1000000+Profiles!$D$5*IF(L32="",0,L32)) | O32: =IF(OR(H32="",I32=""),"",(Profiles!$B$6*(Profiles!$B$10*H32+Profiles!$B$9*IF(J32="",H32,J32)+Profiles!$B$11*IF(K32="",H32,K32))+Profiles!$C$6*I32)/1000000+Profiles!$D$6*IF(L32="",0,L32)) | P32: =IF(OR(H32="",I32=""),"",(Profiles!$B$5*(Profiles!$B$10*H32+Profiles!$B$9*H32+Profiles!$B$11*H32)+Profiles!$C$5*I32)/1000000+Profiles!$D$5*IF(L32="",0,L32)) | Q32: 2026-08-26
A33: openai/gpt-5.4-nano | B33: OpenAI: GPT-5.4 Nano | D33: yes | E33: yes | F33: 400000 | H33: 0.2 | I33: 1.25 | J33: 0.02 | M33: =IF(OR(H33="",I33=""),"",(Profiles!$B$4*(Profiles!$B$10*H33+Profiles!$B$9*IF(J33="",H33,J33)+Profiles!$B$11*IF(K33="",H33,K33))+Profiles!$C$4*I33)/1000000+Profiles!$D$4*IF(L33="",0,L33)) | N33: =IF(OR(H33="",I33=""),"",(Profiles!$B$5*(Profiles!$B$10*H33+Profiles!$B$9*IF(J33="",H33,J33)+Profiles!$B$11*IF(K33="",H33,K33))+Profiles!$C$5*I33)/1000000+Profiles!$D$5*IF(L33="",0,L33)) | O33: =IF(OR(H33="",I33=""),"",(Profiles!$B$6*(Profiles!$B$10*H33+Profiles!$B$9*IF(J33="",H33,J33)+Profiles!$B$11*IF(K33="",H33,K33))+Profiles!$C$6*I33)/1000000+Profiles!$D$6*IF(L33="",0,L33)) | P33: =IF(OR(H33="",I33=""),"",(Profiles!$B$5*(Profiles!$B$10*H33+Profiles!$B$9*H33+Profiles!$B$11*H33)+Profiles!$C$5*I33)/1000000+Profiles!$D$5*IF(L33="",0,L33)) | Q33: 2026-03-17
A34: google/gemma-3-27b-it | B34: Google: Gemma 3 27B | D34: yes | E34: yes | F34: 131072 | H34: 0.08 | I34: 0.45 | J34: 0.04 | M34: =IF(OR(H34="",I34=""),"",(Profiles!$B$4*(Profiles!$B$10*H34+Profiles!$B$9*IF(J34="",H34,J34)+Profiles!$B$11*IF(K34="",H34,K34))+Profiles!$C$4*I34)/1000000+Profiles!$D$4*IF(L34="",0,L34)) | N34: =IF(OR(H34="",I34=""),"",(Profiles!$B$5*(Profiles!$B$10*H34+Profiles!$B$9*IF(J34="",H34,J34)+Profiles!$B$11*IF(K34="",H34,K34))+Profiles!$C$5*I34)/1000000+Profiles!$D$5*IF(L34="",0,L34)) | O34: =IF(OR(H34="",I34=""),"",(Profiles!$B$6*(Profiles!$B$10*H34+Profiles!$B$9*IF(J34="",H34,J34)+Profiles!$B$11*IF(K34="",H34,K34))+Profiles!$C$6*I34)/1000000+Profiles!$D$6*IF(L34="",0,L34)) | P34: =IF(OR(H34="",I34=""),"",(Profiles!$B$5*(Profiles!$B$10*H34+Profiles!$B$9*H34+Profiles!$B$11*H34)+Profiles!$C$5*I34)/1000000+Profiles!$D$5*IF(L34="",0,L34)) | Q34: 2025-03-12
A35: openai/gpt-5.6-luna-pro | B35: OpenAI: GPT-5.6 Luna Pro | D35: yes | E35: yes | F35: 1050000 | H35: 0.2 | I35: 1.2 | J35: 0.02 | K35: 0.25 | M35: =IF(OR(H35="",I35=""),"",(Profiles!$B$4*(Profiles!$B$10*H35+Profiles!$B$9*IF(J35="",H35,J35)+Profiles!$B$11*IF(K35="",H35,K35))+Profiles!$C$4*I35)/1000000+Profiles!$D$4*IF(L35="",0,L35)) | N35: =IF(OR(H35="",I35=""),"",(Profiles!$B$5*(Profiles!$B$10*H35+Profiles!$B$9*IF(J35="",H35,J35)+Profiles!$B$11*IF(K35="",H35,K35))+Profiles!$C$5*I35)/1000000+Profiles!$D$5*IF(L35="",0,L35)) | O35: =IF(OR(H35="",I35=""),"",(Profiles!$B$6*(Profiles!$B$10*H35+Profiles!$B$9*IF(J35="",H35,J35)+Profiles!$B$11*IF(K35="",H35,K35))+Profiles!$C$6*I35)/1000000+Profiles!$D$6*IF(L35="",0,L35)) | P35: =IF(OR(H35="",I35=""),"",(Profiles!$B$5*(Profiles!$B$10*H35+Profiles!$B$9*H35+Profiles!$B$11*H35)+Profiles!$C$5*I35)/1000000+Profiles!$D$5*IF(L35="",0,L35)) | Q35: 2026-07-09
A36: openai/gpt-5.6-luna | B36: OpenAI: GPT-5.6 Luna | D36: yes | E36: yes | F36: 1050000 | H36: 0.2 | I36: 1.2 | J36: 0.02 | K36: 0.25 | M36: =IF(OR(H36="",I36=""),"",(Profiles!$B$4*(Profiles!$B$10*H36+Profiles!$B$9*IF(J36="",H36,J36)+Profiles!$B$11*IF(K36="",H36,K36))+Profiles!$C$4*I36)/1000000+Profiles!$D$4*IF(L36="",0,L36)) | N36: =IF(OR(H36="",I36=""),"",(Profiles!$B$5*(Profiles!$B$10*H36+Profiles!$B$9*IF(J36="",H36,J36)+Profiles!$B$11*IF(K36="",H36,K36))+Profiles!$C$5*I36)/1000000+Profiles!$D$5*IF(L36="",0,L36)) | O36: =IF(OR(H36="",I36=""),"",(Profiles!$B$6*(Profiles!$B$10*H36+Profiles!$B$9*IF(J36="",H36,J36)+Profiles!$B$11*IF(K36="",H36,K36))+Profiles!$C$6*I36)/1000000+Profiles!$D$6*IF(L36="",0,L36)) | P36: =IF(OR(H36="",I36=""),"",(Profiles!$B$5*(Profiles!$B$10*H36+Profiles!$B$9*H36+Profiles!$B$11*H36)+Profiles!$C$5*I36)/1000000+Profiles!$D$5*IF(L36="",0,L36)) | Q36: 2026-07-09
A37: google/gemma-3-12b-it | B37: Google: Gemma 3 12B | D37: yes | E37: yes | F37: 131072 | H37: 0.05 | I37: 0.15 | M37: =IF(OR(H37="",I37=""),"",(Profiles!$B$4*(Profiles!$B$10*H37+Profiles!$B$9*IF(J37="",H37,J37)+Profiles!$B$11*IF(K37="",H37,K37))+Profiles!$C$4*I37)/1000000+Profiles!$D$4*IF(L37="",0,L37)) | N37: =IF(OR(H37="",I37=""),"",(Profiles!$B$5*(Profiles!$B$10*H37+Profiles!$B$9*IF(J37="",H37,J37)+Profiles!$B$11*IF(K37="",H37,K37))+Profiles!$C$5*I37)/1000000+Profiles!$D$5*IF(L37="",0,L37)) | O37: =IF(OR(H37="",I37=""),"",(Profiles!$B$6*(Profiles!$B$10*H37+Profiles!$B$9*IF(J37="",H37,J37)+Profiles!$B$11*IF(K37="",H37,K37))+Profiles!$C$6*I37)/1000000+Profiles!$D$6*IF(L37="",0,L37)) | P37: =IF(OR(H37="",I37=""),"",(Profiles!$B$5*(Profiles!$B$10*H37+Profiles!$B$9*H37+Profiles!$B$11*H37)+Profiles!$C$5*I37)/1000000+Profiles!$D$5*IF(L37="",0,L37)) | Q37: 2025-03-13
A38: google/gemini-3.1-flash-lite | B38: Google: Gemini 3.1 Flash Lite | D38: yes | E38: yes | F38: 1048576 | H38: 0.25 | I38: 1.5 | J38: 0.025 | K38: 0.083333333 | L38: 2.5e-07 | M38: =IF(OR(H38="",I38=""),"",(Profiles!$B$4*(Profiles!$B$10*H38+Profiles!$B$9*IF(J38="",H38,J38)+Profiles!$B$11*IF(K38="",H38,K38))+Profiles!$C$4*I38)/1000000+Profiles!$D$4*IF(L38="",0,L38)) | N38: =IF(OR(H38="",I38=""),"",(Profiles!$B$5*(Profiles!$B$10*H38+Profiles!$B$9*IF(J38="",H38,J38)+Profiles!$B$11*IF(K38="",H38,K38))+Profiles!$C$5*I38)/1000000+Profiles!$D$5*IF(L38="",0,L38)) | O38: =IF(OR(H38="",I38=""),"",(Profiles!$B$6*(Profiles!$B$10*H38+Profiles!$B$9*IF(J38="",H38,J38)+Profiles!$B$11*IF(K38="",H38,K38))+Profiles!$C$6*I38)/1000000+Profiles!$D$6*IF(L38="",0,L38)) | P38: =IF(OR(H38="",I38=""),"",(Profiles!$B$5*(Profiles!$B$10*H38+Profiles!$B$9*H38+Profiles!$B$11*H38)+Profiles!$C$5*I38)/1000000+Profiles!$D$5*IF(L38="",0,L38)) | Q38: 2026-05-07
A39: google/gemini-3.1-flash-lite-preview | B39: Google: Gemini 3.1 Flash Lite Preview | D39: yes | E39: yes | F39: 1048576 | H39: 0.25 | I39: 1.5 | J39: 0.025 | K39: 0.083333333 | L39: 2.5e-07 | M39: =IF(OR(H39="",I39=""),"",(Profiles!$B$4*(Profiles!$B$10*H39+Profiles!$B$9*IF(J39="",H39,J39)+Profiles!$B$11*IF(K39="",H39,K39))+Profiles!$C$4*I39)/1000000+Profiles!$D$4*IF(L39="",0,L39)) | N39: =IF(OR(H39="",I39=""),"",(Profiles!$B$5*(Profiles!$B$10*H39+Profiles!$B$9*IF(J39="",H39,J39)+Profiles!$B$11*IF(K39="",H39,K39))+Profiles!$C$5*I39)/1000000+Profiles!$D$5*IF(L39="",0,L39)) | O39: =IF(OR(H39="",I39=""),"",(Profiles!$B$6*(Profiles!$B$10*H39+Profiles!$B$9*IF(J39="",H39,J39)+Profiles!$B$11*IF(K39="",H39,K39))+Profiles!$C$6*I39)/1000000+Profiles!$D$6*IF(L39="",0,L39)) | P39: =IF(OR(H39="",I39=""),"",(Profiles!$B$5*(Profiles!$B$10*H39+Profiles!$B$9*H39+Profiles!$B$11*H39)+Profiles!$C$5*I39)/1000000+Profiles!$D$5*IF(L39="",0,L39)) | Q39: 2026-03-03
A40: xiaomi/mimo-v2.6-pro | B40: Xiaomi: MiMo-V2.6-Pro | C40: r18, r19 (via Go) | D40: yes | E40: yes | F40: 1050000 | H40: 0.435 | I40: 0.87 | J40: 0.0036 | M40: =IF(OR(H40="",I40=""),"",(Profiles!$B$4*(Profiles!$B$10*H40+Profiles!$B$9*IF(J40="",H40,J40)+Profiles!$B$11*IF(K40="",H40,K40))+Profiles!$C$4*I40)/1000000+Profiles!$D$4*IF(L40="",0,L40)) | N40: =IF(OR(H40="",I40=""),"",(Profiles!$B$5*(Profiles!$B$10*H40+Profiles!$B$9*IF(J40="",H40,J40)+Profiles!$B$11*IF(K40="",H40,K40))+Profiles!$C$5*I40)/1000000+Profiles!$D$5*IF(L40="",0,L40)) | O40: =IF(OR(H40="",I40=""),"",(Profiles!$B$6*(Profiles!$B$10*H40+Profiles!$B$9*IF(J40="",H40,J40)+Profiles!$B$11*IF(K40="",H40,K40))+Profiles!$C$6*I40)/1000000+Profiles!$D$6*IF(L40="",0,L40)) | P40: =IF(OR(H40="",I40=""),"",(Profiles!$B$5*(Profiles!$B$10*H40+Profiles!$B$9*H40+Profiles!$B$11*H40)+Profiles!$C$5*I40)/1000000+Profiles!$D$5*IF(L40="",0,L40)) | Q40: 2026-09-21
...

Sheet Our models
A1: model id | B1: used | C1: light $ | D1: typical $ | E1: heavy $ | F1: typical $ no cache
A2: stealth/space-bunny-alpha | B2: r18 as space-bunny-free (via Go) | C2: =Models!M2 | D2: =Models!N2 | E2: =Models!O2 | F2: =Models!P2
A3: deepseek/deepseek-v4.1-flash | B3: r18 (via Go) | C3: =Models!M12 | D3: =Models!N12 | E3: =Models!O12 | F3: =Models!P12
A4: openai/gpt-6-luna | B4: r19 (via ChatGPT subscription) | C4: =Models!M24 | D4: =Models!N24 | E4: =Models!O24 | F4: =Models!P24
A5: z-ai/glm-5.3-flash | B5: r18 (via Go) | C5: =Models!M32 | D5: =Models!N32 | E5: =Models!O32 | F5: =Models!P32
A6: xiaomi/mimo-v2.6-pro | B6: r18, r19 (via Go) | C6: =Models!M40 | D6: =Models!N40 | E6: =Models!O40 | F6: =Models!P40
A7: google/gemini-3.8-flash | B7: r11, r16, r18, r19 | C7: =Models!M77 | D7: =Models!N77 | E7: =Models!O77 | F7: =Models!P77
A8: meta/muse-spark-1.3 | B8: r18, r19 (via Zen) | C8: =Models!M106 | D8: =Models!N106 | E8: =Models!O106 | F8: =Models!P106
A9: moonshotai/kimi-k3 | B9: r19 (via Go) | C9: =Models!M156 | D9: =Models!N156 | E9: =Models!O156 | F9: =Models!P156
A10: anthropic/claude-opus-5.5 | B10: r10-r17 (Opus 5.5) | C10: =Models!M163 | D10: =Models!N163 | E10: =Models!O163 | F10: =Models!P163
A11: anthropic/claude-fable-5.1 | B11: r11 | C11: =Models!M181 | D11: =Models!N181 | E11: =Models!O181 | F11: =Models!P181
A12: openai/gpt-6-astra | B12: r11, audits | C12: =Models!M184 | D12: =Models!N184 | E12: =Models!O184 | F12: =Models!P184

Sheet Measured paintings
A1: painting | B1: model (provider/id as run) | C1: sittings worked | D1: requests | E1: uncached input | F1: cache read | G1: cache write | H1: output | I1: images | J1: chunks | K1: OpenRouter id | L1: $ at OpenRouter list price
A2: r17-F1 | B2: anthropic/claude-opus-5-5 | C2: 4 | D2: 578 | E2: 1164 | F2: 40539624 | G2: 1371331 | H2: 279722 | I2: 243 | J2: 210 | K2: anthropic/claude-opus-5.5 | L2: 20.563676
A3: r17-F2 | B3: anthropic/claude-opus-5-5 | C3: 3 | D3: 458 | E3: 922 | F3: 44766940 | G3: 4394726 | H3: 223036 | I3: 200 | J3: 184 | K3: anthropic/claude-opus-5.5 | L3: 35.391426
A4: r17-F3 | B4: anthropic/claude-opus-5-5 | C4: 4 | D4: 451 | E4: 910 | F4: 36456995 | G4: 3045368 | H4: 216862 | I4: 178 | J4: 192 | K4: anthropic/claude-opus-5.5 | L4: 26.859119
A5: r17-O1 | B5: anthropic/claude-opus-5-5 | C5: 4 | D5: 206 | E5: 420 | F5: 12571544 | G5: 263115 | H5: 78543 | I5: 98 | J5: 81 | K5: anthropic/claude-opus-5.5 | L5: 5.4024238
A6: r17-O2 | B6: anthropic/claude-opus-5-5 | C6: 4 | D6: 311 | E6: 630 | F6: 15261491 | G6: 1257295 | H6: 100082 | I6: 132 | J6: 120 | K6: anthropic/claude-opus-5.5 | L6: 11.342933
A7: r17-O3 | B7: anthropic/claude-opus-5-5 | C7: 2 | D7: 244 | E7: 492 | F7: 15820196 | G7: 1542897 | H7: 97394 | I7: 106 | J7: 112 | K7: anthropic/claude-opus-5.5 | L7: 12.828372
A8: r18-BUN1 | B8: opencode-go/space-bunny-free | C8: 4 | D8: 826 | E8: 3909565 | F8: 86007256 | G8: 0 | H8: 584717 | I8: 350 | J8: 362 | K8: stealth/space-bunny-alpha | L8: 0
A9: r18-DSK1 | B9: opencode-go/deepseek-v4.1-flash | C9: 4 | D9: 522 | E9: 7020996 | F9: 40720000 | G9: 0 | H9: 400857 | I9: 289 | J9: 172 | K9: deepseek/deepseek-v4.1-flash | L9: 0.40270339
A10: r18-GLM1 | B10: opencode-go/glm-5.3-flash | C10: 5 | D10: 531 | E10: 3635472 | F10: 29874432 | G10: 0 | H10: 186604 | I10: 195 | J10: 189 | K10: z-ai/glm-5.3-flash | L10: 1.5348558
A11: r18-MIMO1 | B11: opencode-go/mimo-v2.6-pro | C11: 3 | D11: 326 | E11: 4784381 | F11: 25242496 | G11: 0 | H11: 251723 | I11: 158 | J11: 79 | K11: xiaomi/mimo-v2.6-pro | L11: 2.3910777
A12: r18-MUSE1 | B12: opencode/muse-spark-1.3 | C12: 2 | D12: 88 | E12: 298624 | F12: 3370328 | G12: 0 | H12: 30130 | I12: 40 | J12: 30 | K12: meta/muse-spark-1.3 | L12: 1.0068817
A13: r18g-GEM1 | B13: google/gemini-3.8-flash | C13: 3 | D13: 336 | E13: 1984860 | F13: 31107408 | G13: 0 | H13: 111795 | I13: 46 | J13: 34 | K13: google/gemini-3.8-flash | L13: 4.2409663
... A21: r19-MUSEF1 | B21: opencode/muse-spark-1.3 | C21: 4 | D21: 349 | E21: 933773 | F21: 19911753 | G21: 0 | H21: 121367 | I21: 204 | J21: 155 | K21: meta/muse-spark-1.3 | L21: 4.669789
